2017-05-13 00:04:01,148 - tornado.application - ERROR - Exception in callback <function praseLog at 0x7ff15b1f7578>
Traceback (most recent call last):
  File "/usr/local/lib/python2.7/dist-packages/tornado/ioloop.py", line 1026, in _run
    return self.callback()
  File "/home/exbot/code/python/tornado/Tjango/contrib/admin/log.py", line 94, in praseLog
    a.parase_log()
  File "/home/exbot/code/python/tornado/Tjango/contrib/admin/log.py", line 33, in parase_log
    latest_log_offset = self.get_lastest_log_offset()
  File "/home/exbot/code/python/tornado/Tjango/contrib/admin/log.py", line 21, in get_lastest_log_offset
    BaseHandler.prepare(self)
  File "/home/exbot/code/python/tornado/Tjango/contrib/admin/view.py", line 18, in prepare
    database.connect()
  File "/usr/local/lib/python2.7/dist-packages/peewee.py", line 3669, in connect
    raise OperationalError('Connection already open')
OperationalError: Connection already open
2017-05-13 00:14:01,137 - tornado.application - ERROR - Exception in callback <function praseLog at 0x7ff15b1f7578>
Traceback (most recent call last):
  File "/usr/local/lib/python2.7/dist-packages/tornado/ioloop.py", line 1026, in _run
    return self.callback()
  File "/home/exbot/code/python/tornado/Tjango/contrib/admin/log.py", line 94, in praseLog
    a.parase_log()
  File "/home/exbot/code/python/tornado/Tjango/contrib/admin/log.py", line 33, in parase_log
    latest_log_offset = self.get_lastest_log_offset()
  File "/home/exbot/code/python/tornado/Tjango/contrib/admin/log.py", line 21, in get_lastest_log_offset
    BaseHandler.prepare(self)
  File "/home/exbot/code/python/tornado/Tjango/contrib/admin/view.py", line 18, in prepare
    database.connect()
  File "/usr/local/lib/python2.7/dist-packages/peewee.py", line 3669, in connect
    raise OperationalError('Connection already open')
OperationalError: Connection already open
2017-05-13 00:24:01,149 - tornado.application - ERROR - Exception in callback <function praseLog at 0x7ff15b1f7578>
Traceback (most recent call last):
  File "/usr/local/lib/python2.7/dist-packages/tornado/ioloop.py", line 1026, in _run
    return self.callback()
  File "/home/exbot/code/python/tornado/Tjango/contrib/admin/log.py", line 94, in praseLog
    a.parase_log()
  File "/home/exbot/code/python/tornado/Tjango/contrib/admin/log.py", line 33, in parase_log
    latest_log_offset = self.get_lastest_log_offset()
  File "/home/exbot/code/python/tornado/Tjango/contrib/admin/log.py", line 21, in get_lastest_log_offset
    BaseHandler.prepare(self)
  File "/home/exbot/code/python/tornado/Tjango/contrib/admin/view.py", line 18, in prepare
    database.connect()
  File "/usr/local/lib/python2.7/dist-packages/peewee.py", line 3669, in connect
    raise OperationalError('Connection already open')
OperationalError: Connection already open
2017-05-13 00:34:01,151 - tornado.application - ERROR - Exception in callback <function praseLog at 0x7ff15b1f7578>
Traceback (most recent call last):
  File "/usr/local/lib/python2.7/dist-packages/tornado/ioloop.py", line 1026, in _run
    return self.callback()
  File "/home/exbot/code/python/tornado/Tjango/contrib/admin/log.py", line 94, in praseLog
    a.parase_log()
  File "/home/exbot/code/python/tornado/Tjango/contrib/admin/log.py", line 33, in parase_log
    latest_log_offset = self.get_lastest_log_offset()
  File "/home/exbot/code/python/tornado/Tjango/contrib/admin/log.py", line 21, in get_lastest_log_offset
    BaseHandler.prepare(self)
  File "/home/exbot/code/python/tornado/Tjango/contrib/admin/view.py", line 18, in prepare
    database.connect()
  File "/usr/local/lib/python2.7/dist-packages/peewee.py", line 3669, in connect
    raise OperationalError('Connection already open')
OperationalError: Connection already open
2017-05-13 00:44:01,130 - tornado.application - ERROR - Exception in callback <function praseLog at 0x7ff15b1f7578>
Traceback (most recent call last):
  File "/usr/local/lib/python2.7/dist-packages/tornado/ioloop.py", line 1026, in _run
    return self.callback()
  File "/home/exbot/code/python/tornado/Tjango/contrib/admin/log.py", line 94, in praseLog
    a.parase_log()
  File "/home/exbot/code/python/tornado/Tjango/contrib/admin/log.py", line 33, in parase_log
    latest_log_offset = self.get_lastest_log_offset()
  File "/home/exbot/code/python/tornado/Tjango/contrib/admin/log.py", line 21, in get_lastest_log_offset
    BaseHandler.prepare(self)
  File "/home/exbot/code/python/tornado/Tjango/contrib/admin/view.py", line 18, in prepare
    database.connect()
  File "/usr/local/lib/python2.7/dist-packages/peewee.py", line 3669, in connect
    raise OperationalError('Connection already open')
OperationalError: Connection already open
2017-05-13 00:54:01,150 - tornado.application - ERROR - Exception in callback <function praseLog at 0x7ff15b1f7578>
Traceback (most recent call last):
  File "/usr/local/lib/python2.7/dist-packages/tornado/ioloop.py", line 1026, in _run
    return self.callback()
  File "/home/exbot/code/python/tornado/Tjango/contrib/admin/log.py", line 94, in praseLog
    a.parase_log()
  File "/home/exbot/code/python/tornado/Tjango/contrib/admin/log.py", line 33, in parase_log
    latest_log_offset = self.get_lastest_log_offset()
  File "/home/exbot/code/python/tornado/Tjango/contrib/admin/log.py", line 21, in get_lastest_log_offset
    BaseHandler.prepare(self)
  File "/home/exbot/code/python/tornado/Tjango/contrib/admin/view.py", line 18, in prepare
    database.connect()
  File "/usr/local/lib/python2.7/dist-packages/peewee.py", line 3669, in connect
    raise OperationalError('Connection already open')
OperationalError: Connection already open
2017-05-13 01:04:01,135 - tornado.application - ERROR - Exception in callback <function praseLog at 0x7ff15b1f7578>
Traceback (most recent call last):
  File "/usr/local/lib/python2.7/dist-packages/tornado/ioloop.py", line 1026, in _run
    return self.callback()
  File "/home/exbot/code/python/tornado/Tjango/contrib/admin/log.py", line 94, in praseLog
    a.parase_log()
  File "/home/exbot/code/python/tornado/Tjango/contrib/admin/log.py", line 33, in parase_log
    latest_log_offset = self.get_lastest_log_offset()
  File "/home/exbot/code/python/tornado/Tjango/contrib/admin/log.py", line 21, in get_lastest_log_offset
    BaseHandler.prepare(self)
  File "/home/exbot/code/python/tornado/Tjango/contrib/admin/view.py", line 18, in prepare
    database.connect()
  File "/usr/local/lib/python2.7/dist-packages/peewee.py", line 3669, in connect
    raise OperationalError('Connection already open')
OperationalError: Connection already open
2017-05-13 01:14:01,100 - tornado.application - ERROR - Exception in callback <function praseLog at 0x7ff15b1f7578>
Traceback (most recent call last):
  File "/usr/local/lib/python2.7/dist-packages/tornado/ioloop.py", line 1026, in _run
    return self.callback()
  File "/home/exbot/code/python/tornado/Tjango/contrib/admin/log.py", line 94, in praseLog
    a.parase_log()
  File "/home/exbot/code/python/tornado/Tjango/contrib/admin/log.py", line 33, in parase_log
    latest_log_offset = self.get_lastest_log_offset()
  File "/home/exbot/code/python/tornado/Tjango/contrib/admin/log.py", line 21, in get_lastest_log_offset
    BaseHandler.prepare(self)
  File "/home/exbot/code/python/tornado/Tjango/contrib/admin/view.py", line 18, in prepare
    database.connect()
  File "/usr/local/lib/python2.7/dist-packages/peewee.py", line 3669, in connect
    raise OperationalError('Connection already open')
OperationalError: Connection already open
2017-05-13 01:24:01,141 - tornado.application - ERROR - Exception in callback <function praseLog at 0x7ff15b1f7578>
Traceback (most recent call last):
  File "/usr/local/lib/python2.7/dist-packages/tornado/ioloop.py", line 1026, in _run
    return self.callback()
  File "/home/exbot/code/python/tornado/Tjango/contrib/admin/log.py", line 94, in praseLog
    a.parase_log()
  File "/home/exbot/code/python/tornado/Tjango/contrib/admin/log.py", line 33, in parase_log
    latest_log_offset = self.get_lastest_log_offset()
  File "/home/exbot/code/python/tornado/Tjango/contrib/admin/log.py", line 21, in get_lastest_log_offset
    BaseHandler.prepare(self)
  File "/home/exbot/code/python/tornado/Tjango/contrib/admin/view.py", line 18, in prepare
    database.connect()
  File "/usr/local/lib/python2.7/dist-packages/peewee.py", line 3669, in connect
    raise OperationalError('Connection already open')
OperationalError: Connection already open
2017-05-13 12:40:31,669 - tornado.application - ERROR - Exception in callback <function praseLog at 0x7ff15b1f7578>
Traceback (most recent call last):
  File "/usr/local/lib/python2.7/dist-packages/tornado/ioloop.py", line 1026, in _run
    return self.callback()
  File "/home/exbot/code/python/tornado/Tjango/contrib/admin/log.py", line 94, in praseLog
    a.parase_log()
  File "/home/exbot/code/python/tornado/Tjango/contrib/admin/log.py", line 33, in parase_log
    latest_log_offset = self.get_lastest_log_offset()
  File "/home/exbot/code/python/tornado/Tjango/contrib/admin/log.py", line 21, in get_lastest_log_offset
    BaseHandler.prepare(self)
  File "/home/exbot/code/python/tornado/Tjango/contrib/admin/view.py", line 18, in prepare
    database.connect()
  File "/usr/local/lib/python2.7/dist-packages/peewee.py", line 3669, in connect
    raise OperationalError('Connection already open')
OperationalError: Connection already open
2017-05-13 12:44:01,149 - tornado.application - ERROR - Exception in callback <function praseLog at 0x7ff15b1f7578>
Traceback (most recent call last):
  File "/usr/local/lib/python2.7/dist-packages/tornado/ioloop.py", line 1026, in _run
    return self.callback()
  File "/home/exbot/code/python/tornado/Tjango/contrib/admin/log.py", line 94, in praseLog
    a.parase_log()
  File "/home/exbot/code/python/tornado/Tjango/contrib/admin/log.py", line 33, in parase_log
    latest_log_offset = self.get_lastest_log_offset()
  File "/home/exbot/code/python/tornado/Tjango/contrib/admin/log.py", line 21, in get_lastest_log_offset
    BaseHandler.prepare(self)
  File "/home/exbot/code/python/tornado/Tjango/contrib/admin/view.py", line 18, in prepare
    database.connect()
  File "/usr/local/lib/python2.7/dist-packages/peewee.py", line 3669, in connect
    raise OperationalError('Connection already open')
OperationalError: Connection already open
2017-05-13 12:54:01,141 - tornado.application - ERROR - Exception in callback <function praseLog at 0x7ff15b1f7578>
Traceback (most recent call last):
  File "/usr/local/lib/python2.7/dist-packages/tornado/ioloop.py", line 1026, in _run
    return self.callback()
  File "/home/exbot/code/python/tornado/Tjango/contrib/admin/log.py", line 94, in praseLog
    a.parase_log()
  File "/home/exbot/code/python/tornado/Tjango/contrib/admin/log.py", line 33, in parase_log
    latest_log_offset = self.get_lastest_log_offset()
  File "/home/exbot/code/python/tornado/Tjango/contrib/admin/log.py", line 21, in get_lastest_log_offset
    BaseHandler.prepare(self)
  File "/home/exbot/code/python/tornado/Tjango/contrib/admin/view.py", line 18, in prepare
    database.connect()
  File "/usr/local/lib/python2.7/dist-packages/peewee.py", line 3669, in connect
    raise OperationalError('Connection already open')
OperationalError: Connection already open
2017-05-13 13:04:01,124 - tornado.application - ERROR - Exception in callback <function praseLog at 0x7ff15b1f7578>
Traceback (most recent call last):
  File "/usr/local/lib/python2.7/dist-packages/tornado/ioloop.py", line 1026, in _run
    return self.callback()
  File "/home/exbot/code/python/tornado/Tjango/contrib/admin/log.py", line 94, in praseLog
    a.parase_log()
  File "/home/exbot/code/python/tornado/Tjango/contrib/admin/log.py", line 33, in parase_log
    latest_log_offset = self.get_lastest_log_offset()
  File "/home/exbot/code/python/tornado/Tjango/contrib/admin/log.py", line 21, in get_lastest_log_offset
    BaseHandler.prepare(self)
  File "/home/exbot/code/python/tornado/Tjango/contrib/admin/view.py", line 18, in prepare
    database.connect()
  File "/usr/local/lib/python2.7/dist-packages/peewee.py", line 3669, in connect
    raise OperationalError('Connection already open')
OperationalError: Connection already open
2017-05-13 13:14:01,126 - tornado.application - ERROR - Exception in callback <function praseLog at 0x7ff15b1f7578>
Traceback (most recent call last):
  File "/usr/local/lib/python2.7/dist-packages/tornado/ioloop.py", line 1026, in _run
    return self.callback()
  File "/home/exbot/code/python/tornado/Tjango/contrib/admin/log.py", line 94, in praseLog
    a.parase_log()
  File "/home/exbot/code/python/tornado/Tjango/contrib/admin/log.py", line 33, in parase_log
    latest_log_offset = self.get_lastest_log_offset()
  File "/home/exbot/code/python/tornado/Tjango/contrib/admin/log.py", line 21, in get_lastest_log_offset
    BaseHandler.prepare(self)
  File "/home/exbot/code/python/tornado/Tjango/contrib/admin/view.py", line 18, in prepare
    database.connect()
  File "/usr/local/lib/python2.7/dist-packages/peewee.py", line 3669, in connect
    raise OperationalError('Connection already open')
OperationalError: Connection already open
2017-05-13 13:24:01,149 - tornado.application - ERROR - Exception in callback <function praseLog at 0x7ff15b1f7578>
Traceback (most recent call last):
  File "/usr/local/lib/python2.7/dist-packages/tornado/ioloop.py", line 1026, in _run
    return self.callback()
  File "/home/exbot/code/python/tornado/Tjango/contrib/admin/log.py", line 94, in praseLog
    a.parase_log()
  File "/home/exbot/code/python/tornado/Tjango/contrib/admin/log.py", line 33, in parase_log
    latest_log_offset = self.get_lastest_log_offset()
  File "/home/exbot/code/python/tornado/Tjango/contrib/admin/log.py", line 21, in get_lastest_log_offset
    BaseHandler.prepare(self)
  File "/home/exbot/code/python/tornado/Tjango/contrib/admin/view.py", line 18, in prepare
    database.connect()
  File "/usr/local/lib/python2.7/dist-packages/peewee.py", line 3669, in connect
    raise OperationalError('Connection already open')
OperationalError: Connection already open
2017-05-13 13:34:01,093 - tornado.application - ERROR - Exception in callback <function praseLog at 0x7ff15b1f7578>
Traceback (most recent call last):
  File "/usr/local/lib/python2.7/dist-packages/tornado/ioloop.py", line 1026, in _run
    return self.callback()
  File "/home/exbot/code/python/tornado/Tjango/contrib/admin/log.py", line 94, in praseLog
    a.parase_log()
  File "/home/exbot/code/python/tornado/Tjango/contrib/admin/log.py", line 33, in parase_log
    latest_log_offset = self.get_lastest_log_offset()
  File "/home/exbot/code/python/tornado/Tjango/contrib/admin/log.py", line 21, in get_lastest_log_offset
    BaseHandler.prepare(self)
  File "/home/exbot/code/python/tornado/Tjango/contrib/admin/view.py", line 18, in prepare
    database.connect()
  File "/usr/local/lib/python2.7/dist-packages/peewee.py", line 3669, in connect
    raise OperationalError('Connection already open')
OperationalError: Connection already open
2017-05-13 13:44:01,119 - tornado.application - ERROR - Exception in callback <function praseLog at 0x7ff15b1f7578>
Traceback (most recent call last):
  File "/usr/local/lib/python2.7/dist-packages/tornado/ioloop.py", line 1026, in _run
    return self.callback()
  File "/home/exbot/code/python/tornado/Tjango/contrib/admin/log.py", line 94, in praseLog
    a.parase_log()
  File "/home/exbot/code/python/tornado/Tjango/contrib/admin/log.py", line 33, in parase_log
    latest_log_offset = self.get_lastest_log_offset()
  File "/home/exbot/code/python/tornado/Tjango/contrib/admin/log.py", line 21, in get_lastest_log_offset
    BaseHandler.prepare(self)
  File "/home/exbot/code/python/tornado/Tjango/contrib/admin/view.py", line 18, in prepare
    database.connect()
  File "/usr/local/lib/python2.7/dist-packages/peewee.py", line 3669, in connect
    raise OperationalError('Connection already open')
OperationalError: Connection already open
2017-05-13 13:54:01,145 - tornado.application - ERROR - Exception in callback <function praseLog at 0x7ff15b1f7578>
Traceback (most recent call last):
  File "/usr/local/lib/python2.7/dist-packages/tornado/ioloop.py", line 1026, in _run
    return self.callback()
  File "/home/exbot/code/python/tornado/Tjango/contrib/admin/log.py", line 94, in praseLog
    a.parase_log()
  File "/home/exbot/code/python/tornado/Tjango/contrib/admin/log.py", line 33, in parase_log
    latest_log_offset = self.get_lastest_log_offset()
  File "/home/exbot/code/python/tornado/Tjango/contrib/admin/log.py", line 21, in get_lastest_log_offset
    BaseHandler.prepare(self)
  File "/home/exbot/code/python/tornado/Tjango/contrib/admin/view.py", line 18, in prepare
    database.connect()
  File "/usr/local/lib/python2.7/dist-packages/peewee.py", line 3669, in connect
    raise OperationalError('Connection already open')
OperationalError: Connection already open
2017-05-13 14:04:01,117 - tornado.application - ERROR - Exception in callback <function praseLog at 0x7ff15b1f7578>
Traceback (most recent call last):
  File "/usr/local/lib/python2.7/dist-packages/tornado/ioloop.py", line 1026, in _run
    return self.callback()
  File "/home/exbot/code/python/tornado/Tjango/contrib/admin/log.py", line 94, in praseLog
    a.parase_log()
  File "/home/exbot/code/python/tornado/Tjango/contrib/admin/log.py", line 33, in parase_log
    latest_log_offset = self.get_lastest_log_offset()
  File "/home/exbot/code/python/tornado/Tjango/contrib/admin/log.py", line 21, in get_lastest_log_offset
    BaseHandler.prepare(self)
  File "/home/exbot/code/python/tornado/Tjango/contrib/admin/view.py", line 18, in prepare
    database.connect()
  File "/usr/local/lib/python2.7/dist-packages/peewee.py", line 3669, in connect
    raise OperationalError('Connection already open')
OperationalError: Connection already open
2017-05-13 14:14:01,138 - tornado.application - ERROR - Exception in callback <function praseLog at 0x7ff15b1f7578>
Traceback (most recent call last):
  File "/usr/local/lib/python2.7/dist-packages/tornado/ioloop.py", line 1026, in _run
    return self.callback()
  File "/home/exbot/code/python/tornado/Tjango/contrib/admin/log.py", line 94, in praseLog
    a.parase_log()
  File "/home/exbot/code/python/tornado/Tjango/contrib/admin/log.py", line 33, in parase_log
    latest_log_offset = self.get_lastest_log_offset()
  File "/home/exbot/code/python/tornado/Tjango/contrib/admin/log.py", line 21, in get_lastest_log_offset
    BaseHandler.prepare(self)
  File "/home/exbot/code/python/tornado/Tjango/contrib/admin/view.py", line 18, in prepare
    database.connect()
  File "/usr/local/lib/python2.7/dist-packages/peewee.py", line 3669, in connect
    raise OperationalError('Connection already open')
OperationalError: Connection already open
2017-05-13 14:24:01,141 - tornado.application - ERROR - Exception in callback <function praseLog at 0x7ff15b1f7578>
Traceback (most recent call last):
  File "/usr/local/lib/python2.7/dist-packages/tornado/ioloop.py", line 1026, in _run
    return self.callback()
  File "/home/exbot/code/python/tornado/Tjango/contrib/admin/log.py", line 94, in praseLog
    a.parase_log()
  File "/home/exbot/code/python/tornado/Tjango/contrib/admin/log.py", line 33, in parase_log
    latest_log_offset = self.get_lastest_log_offset()
  File "/home/exbot/code/python/tornado/Tjango/contrib/admin/log.py", line 21, in get_lastest_log_offset
    BaseHandler.prepare(self)
  File "/home/exbot/code/python/tornado/Tjango/contrib/admin/view.py", line 18, in prepare
    database.connect()
  File "/usr/local/lib/python2.7/dist-packages/peewee.py", line 3669, in connect
    raise OperationalError('Connection already open')
OperationalError: Connection already open
2017-05-13 14:34:01,148 - tornado.application - ERROR - Exception in callback <function praseLog at 0x7ff15b1f7578>
Traceback (most recent call last):
  File "/usr/local/lib/python2.7/dist-packages/tornado/ioloop.py", line 1026, in _run
    return self.callback()
  File "/home/exbot/code/python/tornado/Tjango/contrib/admin/log.py", line 94, in praseLog
    a.parase_log()
  File "/home/exbot/code/python/tornado/Tjango/contrib/admin/log.py", line 33, in parase_log
    latest_log_offset = self.get_lastest_log_offset()
  File "/home/exbot/code/python/tornado/Tjango/contrib/admin/log.py", line 21, in get_lastest_log_offset
    BaseHandler.prepare(self)
  File "/home/exbot/code/python/tornado/Tjango/contrib/admin/view.py", line 18, in prepare
    database.connect()
  File "/usr/local/lib/python2.7/dist-packages/peewee.py", line 3669, in connect
    raise OperationalError('Connection already open')
OperationalError: Connection already open
2017-05-13 14:44:01,130 - tornado.application - ERROR - Exception in callback <function praseLog at 0x7ff15b1f7578>
Traceback (most recent call last):
  File "/usr/local/lib/python2.7/dist-packages/tornado/ioloop.py", line 1026, in _run
    return self.callback()
  File "/home/exbot/code/python/tornado/Tjango/contrib/admin/log.py", line 94, in praseLog
    a.parase_log()
  File "/home/exbot/code/python/tornado/Tjango/contrib/admin/log.py", line 33, in parase_log
    latest_log_offset = self.get_lastest_log_offset()
  File "/home/exbot/code/python/tornado/Tjango/contrib/admin/log.py", line 21, in get_lastest_log_offset
    BaseHandler.prepare(self)
  File "/home/exbot/code/python/tornado/Tjango/contrib/admin/view.py", line 18, in prepare
    database.connect()
  File "/usr/local/lib/python2.7/dist-packages/peewee.py", line 3669, in connect
    raise OperationalError('Connection already open')
OperationalError: Connection already open
2017-05-13 14:54:01,141 - tornado.application - ERROR - Exception in callback <function praseLog at 0x7ff15b1f7578>
Traceback (most recent call last):
  File "/usr/local/lib/python2.7/dist-packages/tornado/ioloop.py", line 1026, in _run
    return self.callback()
  File "/home/exbot/code/python/tornado/Tjango/contrib/admin/log.py", line 94, in praseLog
    a.parase_log()
  File "/home/exbot/code/python/tornado/Tjango/contrib/admin/log.py", line 33, in parase_log
    latest_log_offset = self.get_lastest_log_offset()
  File "/home/exbot/code/python/tornado/Tjango/contrib/admin/log.py", line 21, in get_lastest_log_offset
    BaseHandler.prepare(self)
  File "/home/exbot/code/python/tornado/Tjango/contrib/admin/view.py", line 18, in prepare
    database.connect()
  File "/usr/local/lib/python2.7/dist-packages/peewee.py", line 3669, in connect
    raise OperationalError('Connection already open')
OperationalError: Connection already open
2017-05-13 15:04:01,141 - tornado.application - ERROR - Exception in callback <function praseLog at 0x7ff15b1f7578>
Traceback (most recent call last):
  File "/usr/local/lib/python2.7/dist-packages/tornado/ioloop.py", line 1026, in _run
    return self.callback()
  File "/home/exbot/code/python/tornado/Tjango/contrib/admin/log.py", line 94, in praseLog
    a.parase_log()
  File "/home/exbot/code/python/tornado/Tjango/contrib/admin/log.py", line 33, in parase_log
    latest_log_offset = self.get_lastest_log_offset()
  File "/home/exbot/code/python/tornado/Tjango/contrib/admin/log.py", line 21, in get_lastest_log_offset
    BaseHandler.prepare(self)
  File "/home/exbot/code/python/tornado/Tjango/contrib/admin/view.py", line 18, in prepare
    database.connect()
  File "/usr/local/lib/python2.7/dist-packages/peewee.py", line 3669, in connect
    raise OperationalError('Connection already open')
OperationalError: Connection already open
2017-05-13 15:14:01,150 - tornado.application - ERROR - Exception in callback <function praseLog at 0x7ff15b1f7578>
Traceback (most recent call last):
  File "/usr/local/lib/python2.7/dist-packages/tornado/ioloop.py", line 1026, in _run
    return self.callback()
  File "/home/exbot/code/python/tornado/Tjango/contrib/admin/log.py", line 94, in praseLog
    a.parase_log()
  File "/home/exbot/code/python/tornado/Tjango/contrib/admin/log.py", line 33, in parase_log
    latest_log_offset = self.get_lastest_log_offset()
  File "/home/exbot/code/python/tornado/Tjango/contrib/admin/log.py", line 21, in get_lastest_log_offset
    BaseHandler.prepare(self)
  File "/home/exbot/code/python/tornado/Tjango/contrib/admin/view.py", line 18, in prepare
    database.connect()
  File "/usr/local/lib/python2.7/dist-packages/peewee.py", line 3669, in connect
    raise OperationalError('Connection already open')
OperationalError: Connection already open
2017-05-13 15:24:01,075 - tornado.application - ERROR - Exception in callback <function praseLog at 0x7ff15b1f7578>
Traceback (most recent call last):
  File "/usr/local/lib/python2.7/dist-packages/tornado/ioloop.py", line 1026, in _run
    return self.callback()
  File "/home/exbot/code/python/tornado/Tjango/contrib/admin/log.py", line 94, in praseLog
    a.parase_log()
  File "/home/exbot/code/python/tornado/Tjango/contrib/admin/log.py", line 33, in parase_log
    latest_log_offset = self.get_lastest_log_offset()
  File "/home/exbot/code/python/tornado/Tjango/contrib/admin/log.py", line 21, in get_lastest_log_offset
    BaseHandler.prepare(self)
  File "/home/exbot/code/python/tornado/Tjango/contrib/admin/view.py", line 18, in prepare
    database.connect()
  File "/usr/local/lib/python2.7/dist-packages/peewee.py", line 3669, in connect
    raise OperationalError('Connection already open')
OperationalError: Connection already open
2017-05-13 15:34:01,150 - tornado.application - ERROR - Exception in callback <function praseLog at 0x7ff15b1f7578>
Traceback (most recent call last):
  File "/usr/local/lib/python2.7/dist-packages/tornado/ioloop.py", line 1026, in _run
    return self.callback()
  File "/home/exbot/code/python/tornado/Tjango/contrib/admin/log.py", line 94, in praseLog
    a.parase_log()
  File "/home/exbot/code/python/tornado/Tjango/contrib/admin/log.py", line 33, in parase_log
    latest_log_offset = self.get_lastest_log_offset()
  File "/home/exbot/code/python/tornado/Tjango/contrib/admin/log.py", line 21, in get_lastest_log_offset
    BaseHandler.prepare(self)
  File "/home/exbot/code/python/tornado/Tjango/contrib/admin/view.py", line 18, in prepare
    database.connect()
  File "/usr/local/lib/python2.7/dist-packages/peewee.py", line 3669, in connect
    raise OperationalError('Connection already open')
OperationalError: Connection already open
2017-05-13 15:44:01,132 - tornado.application - ERROR - Exception in callback <function praseLog at 0x7ff15b1f7578>
Traceback (most recent call last):
  File "/usr/local/lib/python2.7/dist-packages/tornado/ioloop.py", line 1026, in _run
    return self.callback()
  File "/home/exbot/code/python/tornado/Tjango/contrib/admin/log.py", line 94, in praseLog
    a.parase_log()
  File "/home/exbot/code/python/tornado/Tjango/contrib/admin/log.py", line 33, in parase_log
    latest_log_offset = self.get_lastest_log_offset()
  File "/home/exbot/code/python/tornado/Tjango/contrib/admin/log.py", line 21, in get_lastest_log_offset
    BaseHandler.prepare(self)
  File "/home/exbot/code/python/tornado/Tjango/contrib/admin/view.py", line 18, in prepare
    database.connect()
  File "/usr/local/lib/python2.7/dist-packages/peewee.py", line 3669, in connect
    raise OperationalError('Connection already open')
OperationalError: Connection already open
2017-05-13 15:54:01,094 - tornado.application - ERROR - Exception in callback <function praseLog at 0x7ff15b1f7578>
Traceback (most recent call last):
  File "/usr/local/lib/python2.7/dist-packages/tornado/ioloop.py", line 1026, in _run
    return self.callback()
  File "/home/exbot/code/python/tornado/Tjango/contrib/admin/log.py", line 94, in praseLog
    a.parase_log()
  File "/home/exbot/code/python/tornado/Tjango/contrib/admin/log.py", line 33, in parase_log
    latest_log_offset = self.get_lastest_log_offset()
  File "/home/exbot/code/python/tornado/Tjango/contrib/admin/log.py", line 21, in get_lastest_log_offset
    BaseHandler.prepare(self)
  File "/home/exbot/code/python/tornado/Tjango/contrib/admin/view.py", line 18, in prepare
    database.connect()
  File "/usr/local/lib/python2.7/dist-packages/peewee.py", line 3669, in connect
    raise OperationalError('Connection already open')
OperationalError: Connection already open
2017-05-13 16:04:01,146 - tornado.application - ERROR - Exception in callback <function praseLog at 0x7ff15b1f7578>
Traceback (most recent call last):
  File "/usr/local/lib/python2.7/dist-packages/tornado/ioloop.py", line 1026, in _run
    return self.callback()
  File "/home/exbot/code/python/tornado/Tjango/contrib/admin/log.py", line 94, in praseLog
    a.parase_log()
  File "/home/exbot/code/python/tornado/Tjango/contrib/admin/log.py", line 33, in parase_log
    latest_log_offset = self.get_lastest_log_offset()
  File "/home/exbot/code/python/tornado/Tjango/contrib/admin/log.py", line 21, in get_lastest_log_offset
    BaseHandler.prepare(self)
  File "/home/exbot/code/python/tornado/Tjango/contrib/admin/view.py", line 18, in prepare
    database.connect()
  File "/usr/local/lib/python2.7/dist-packages/peewee.py", line 3669, in connect
    raise OperationalError('Connection already open')
OperationalError: Connection already open
2017-05-13 16:14:01,146 - tornado.application - ERROR - Exception in callback <function praseLog at 0x7ff15b1f7578>
Traceback (most recent call last):
  File "/usr/local/lib/python2.7/dist-packages/tornado/ioloop.py", line 1026, in _run
    return self.callback()
  File "/home/exbot/code/python/tornado/Tjango/contrib/admin/log.py", line 94, in praseLog
    a.parase_log()
  File "/home/exbot/code/python/tornado/Tjango/contrib/admin/log.py", line 33, in parase_log
    latest_log_offset = self.get_lastest_log_offset()
  File "/home/exbot/code/python/tornado/Tjango/contrib/admin/log.py", line 21, in get_lastest_log_offset
    BaseHandler.prepare(self)
  File "/home/exbot/code/python/tornado/Tjango/contrib/admin/view.py", line 18, in prepare
    database.connect()
  File "/usr/local/lib/python2.7/dist-packages/peewee.py", line 3669, in connect
    raise OperationalError('Connection already open')
OperationalError: Connection already open
2017-05-13 16:24:01,145 - tornado.application - ERROR - Exception in callback <function praseLog at 0x7ff15b1f7578>
Traceback (most recent call last):
  File "/usr/local/lib/python2.7/dist-packages/tornado/ioloop.py", line 1026, in _run
    return self.callback()
  File "/home/exbot/code/python/tornado/Tjango/contrib/admin/log.py", line 94, in praseLog
    a.parase_log()
  File "/home/exbot/code/python/tornado/Tjango/contrib/admin/log.py", line 33, in parase_log
    latest_log_offset = self.get_lastest_log_offset()
  File "/home/exbot/code/python/tornado/Tjango/contrib/admin/log.py", line 21, in get_lastest_log_offset
    BaseHandler.prepare(self)
  File "/home/exbot/code/python/tornado/Tjango/contrib/admin/view.py", line 18, in prepare
    database.connect()
  File "/usr/local/lib/python2.7/dist-packages/peewee.py", line 3669, in connect
    raise OperationalError('Connection already open')
OperationalError: Connection already open
2017-05-13 16:34:01,070 - tornado.application - ERROR - Exception in callback <function praseLog at 0x7ff15b1f7578>
Traceback (most recent call last):
  File "/usr/local/lib/python2.7/dist-packages/tornado/ioloop.py", line 1026, in _run
    return self.callback()
  File "/home/exbot/code/python/tornado/Tjango/contrib/admin/log.py", line 94, in praseLog
    a.parase_log()
  File "/home/exbot/code/python/tornado/Tjango/contrib/admin/log.py", line 33, in parase_log
    latest_log_offset = self.get_lastest_log_offset()
  File "/home/exbot/code/python/tornado/Tjango/contrib/admin/log.py", line 21, in get_lastest_log_offset
    BaseHandler.prepare(self)
  File "/home/exbot/code/python/tornado/Tjango/contrib/admin/view.py", line 18, in prepare
    database.connect()
  File "/usr/local/lib/python2.7/dist-packages/peewee.py", line 3669, in connect
    raise OperationalError('Connection already open')
OperationalError: Connection already open
2017-05-13 16:44:01,121 - tornado.application - ERROR - Exception in callback <function praseLog at 0x7ff15b1f7578>
Traceback (most recent call last):
  File "/usr/local/lib/python2.7/dist-packages/tornado/ioloop.py", line 1026, in _run
    return self.callback()
  File "/home/exbot/code/python/tornado/Tjango/contrib/admin/log.py", line 94, in praseLog
    a.parase_log()
  File "/home/exbot/code/python/tornado/Tjango/contrib/admin/log.py", line 33, in parase_log
    latest_log_offset = self.get_lastest_log_offset()
  File "/home/exbot/code/python/tornado/Tjango/contrib/admin/log.py", line 21, in get_lastest_log_offset
    BaseHandler.prepare(self)
  File "/home/exbot/code/python/tornado/Tjango/contrib/admin/view.py", line 18, in prepare
    database.connect()
  File "/usr/local/lib/python2.7/dist-packages/peewee.py", line 3669, in connect
    raise OperationalError('Connection already open')
OperationalError: Connection already open
2017-05-13 16:54:01,098 - tornado.application - ERROR - Exception in callback <function praseLog at 0x7ff15b1f7578>
Traceback (most recent call last):
  File "/usr/local/lib/python2.7/dist-packages/tornado/ioloop.py", line 1026, in _run
    return self.callback()
  File "/home/exbot/code/python/tornado/Tjango/contrib/admin/log.py", line 94, in praseLog
    a.parase_log()
  File "/home/exbot/code/python/tornado/Tjango/contrib/admin/log.py", line 33, in parase_log
    latest_log_offset = self.get_lastest_log_offset()
  File "/home/exbot/code/python/tornado/Tjango/contrib/admin/log.py", line 21, in get_lastest_log_offset
    BaseHandler.prepare(self)
  File "/home/exbot/code/python/tornado/Tjango/contrib/admin/view.py", line 18, in prepare
    database.connect()
  File "/usr/local/lib/python2.7/dist-packages/peewee.py", line 3669, in connect
    raise OperationalError('Connection already open')
OperationalError: Connection already open
2017-05-13 17:04:01,131 - tornado.application - ERROR - Exception in callback <function praseLog at 0x7ff15b1f7578>
Traceback (most recent call last):
  File "/usr/local/lib/python2.7/dist-packages/tornado/ioloop.py", line 1026, in _run
    return self.callback()
  File "/home/exbot/code/python/tornado/Tjango/contrib/admin/log.py", line 94, in praseLog
    a.parase_log()
  File "/home/exbot/code/python/tornado/Tjango/contrib/admin/log.py", line 33, in parase_log
    latest_log_offset = self.get_lastest_log_offset()
  File "/home/exbot/code/python/tornado/Tjango/contrib/admin/log.py", line 21, in get_lastest_log_offset
    BaseHandler.prepare(self)
  File "/home/exbot/code/python/tornado/Tjango/contrib/admin/view.py", line 18, in prepare
    database.connect()
  File "/usr/local/lib/python2.7/dist-packages/peewee.py", line 3669, in connect
    raise OperationalError('Connection already open')
OperationalError: Connection already open
2017-05-13 17:14:01,112 - tornado.application - ERROR - Exception in callback <function praseLog at 0x7ff15b1f7578>
Traceback (most recent call last):
  File "/usr/local/lib/python2.7/dist-packages/tornado/ioloop.py", line 1026, in _run
    return self.callback()
  File "/home/exbot/code/python/tornado/Tjango/contrib/admin/log.py", line 94, in praseLog
    a.parase_log()
  File "/home/exbot/code/python/tornado/Tjango/contrib/admin/log.py", line 33, in parase_log
    latest_log_offset = self.get_lastest_log_offset()
  File "/home/exbot/code/python/tornado/Tjango/contrib/admin/log.py", line 21, in get_lastest_log_offset
    BaseHandler.prepare(self)
  File "/home/exbot/code/python/tornado/Tjango/contrib/admin/view.py", line 18, in prepare
    database.connect()
  File "/usr/local/lib/python2.7/dist-packages/peewee.py", line 3669, in connect
    raise OperationalError('Connection already open')
OperationalError: Connection already open
2017-05-13 17:24:01,151 - tornado.application - ERROR - Exception in callback <function praseLog at 0x7ff15b1f7578>
Traceback (most recent call last):
  File "/usr/local/lib/python2.7/dist-packages/tornado/ioloop.py", line 1026, in _run
    return self.callback()
  File "/home/exbot/code/python/tornado/Tjango/contrib/admin/log.py", line 94, in praseLog
    a.parase_log()
  File "/home/exbot/code/python/tornado/Tjango/contrib/admin/log.py", line 33, in parase_log
    latest_log_offset = self.get_lastest_log_offset()
  File "/home/exbot/code/python/tornado/Tjango/contrib/admin/log.py", line 21, in get_lastest_log_offset
    BaseHandler.prepare(self)
  File "/home/exbot/code/python/tornado/Tjango/contrib/admin/view.py", line 18, in prepare
    database.connect()
  File "/usr/local/lib/python2.7/dist-packages/peewee.py", line 3669, in connect
    raise OperationalError('Connection already open')
OperationalError: Connection already open
2017-05-13 17:34:01,132 - tornado.application - ERROR - Exception in callback <function praseLog at 0x7ff15b1f7578>
Traceback (most recent call last):
  File "/usr/local/lib/python2.7/dist-packages/tornado/ioloop.py", line 1026, in _run
    return self.callback()
  File "/home/exbot/code/python/tornado/Tjango/contrib/admin/log.py", line 94, in praseLog
    a.parase_log()
  File "/home/exbot/code/python/tornado/Tjango/contrib/admin/log.py", line 33, in parase_log
    latest_log_offset = self.get_lastest_log_offset()
  File "/home/exbot/code/python/tornado/Tjango/contrib/admin/log.py", line 21, in get_lastest_log_offset
    BaseHandler.prepare(self)
  File "/home/exbot/code/python/tornado/Tjango/contrib/admin/view.py", line 18, in prepare
    database.connect()
  File "/usr/local/lib/python2.7/dist-packages/peewee.py", line 3669, in connect
    raise OperationalError('Connection already open')
OperationalError: Connection already open
2017-05-13 17:44:01,150 - tornado.application - ERROR - Exception in callback <function praseLog at 0x7ff15b1f7578>
Traceback (most recent call last):
  File "/usr/local/lib/python2.7/dist-packages/tornado/ioloop.py", line 1026, in _run
    return self.callback()
  File "/home/exbot/code/python/tornado/Tjango/contrib/admin/log.py", line 94, in praseLog
    a.parase_log()
  File "/home/exbot/code/python/tornado/Tjango/contrib/admin/log.py", line 33, in parase_log
    latest_log_offset = self.get_lastest_log_offset()
  File "/home/exbot/code/python/tornado/Tjango/contrib/admin/log.py", line 21, in get_lastest_log_offset
    BaseHandler.prepare(self)
  File "/home/exbot/code/python/tornado/Tjango/contrib/admin/view.py", line 18, in prepare
    database.connect()
  File "/usr/local/lib/python2.7/dist-packages/peewee.py", line 3669, in connect
    raise OperationalError('Connection already open')
OperationalError: Connection already open
2017-05-13 17:54:01,093 - tornado.application - ERROR - Exception in callback <function praseLog at 0x7ff15b1f7578>
Traceback (most recent call last):
  File "/usr/local/lib/python2.7/dist-packages/tornado/ioloop.py", line 1026, in _run
    return self.callback()
  File "/home/exbot/code/python/tornado/Tjango/contrib/admin/log.py", line 94, in praseLog
    a.parase_log()
  File "/home/exbot/code/python/tornado/Tjango/contrib/admin/log.py", line 33, in parase_log
    latest_log_offset = self.get_lastest_log_offset()
  File "/home/exbot/code/python/tornado/Tjango/contrib/admin/log.py", line 21, in get_lastest_log_offset
    BaseHandler.prepare(self)
  File "/home/exbot/code/python/tornado/Tjango/contrib/admin/view.py", line 18, in prepare
    database.connect()
  File "/usr/local/lib/python2.7/dist-packages/peewee.py", line 3669, in connect
    raise OperationalError('Connection already open')
OperationalError: Connection already open
2017-05-13 18:04:01,140 - tornado.application - ERROR - Exception in callback <function praseLog at 0x7ff15b1f7578>
Traceback (most recent call last):
  File "/usr/local/lib/python2.7/dist-packages/tornado/ioloop.py", line 1026, in _run
    return self.callback()
  File "/home/exbot/code/python/tornado/Tjango/contrib/admin/log.py", line 94, in praseLog
    a.parase_log()
  File "/home/exbot/code/python/tornado/Tjango/contrib/admin/log.py", line 33, in parase_log
    latest_log_offset = self.get_lastest_log_offset()
  File "/home/exbot/code/python/tornado/Tjango/contrib/admin/log.py", line 21, in get_lastest_log_offset
    BaseHandler.prepare(self)
  File "/home/exbot/code/python/tornado/Tjango/contrib/admin/view.py", line 18, in prepare
    database.connect()
  File "/usr/local/lib/python2.7/dist-packages/peewee.py", line 3669, in connect
    raise OperationalError('Connection already open')
OperationalError: Connection already open
2017-05-13 18:14:01,058 - tornado.application - ERROR - Exception in callback <function praseLog at 0x7ff15b1f7578>
Traceback (most recent call last):
  File "/usr/local/lib/python2.7/dist-packages/tornado/ioloop.py", line 1026, in _run
    return self.callback()
  File "/home/exbot/code/python/tornado/Tjango/contrib/admin/log.py", line 94, in praseLog
    a.parase_log()
  File "/home/exbot/code/python/tornado/Tjango/contrib/admin/log.py", line 33, in parase_log
    latest_log_offset = self.get_lastest_log_offset()
  File "/home/exbot/code/python/tornado/Tjango/contrib/admin/log.py", line 21, in get_lastest_log_offset
    BaseHandler.prepare(self)
  File "/home/exbot/code/python/tornado/Tjango/contrib/admin/view.py", line 18, in prepare
    database.connect()
  File "/usr/local/lib/python2.7/dist-packages/peewee.py", line 3669, in connect
    raise OperationalError('Connection already open')
OperationalError: Connection already open
2017-05-13 18:24:01,066 - tornado.application - ERROR - Exception in callback <function praseLog at 0x7ff15b1f7578>
Traceback (most recent call last):
  File "/usr/local/lib/python2.7/dist-packages/tornado/ioloop.py", line 1026, in _run
    return self.callback()
  File "/home/exbot/code/python/tornado/Tjango/contrib/admin/log.py", line 94, in praseLog
    a.parase_log()
  File "/home/exbot/code/python/tornado/Tjango/contrib/admin/log.py", line 33, in parase_log
    latest_log_offset = self.get_lastest_log_offset()
  File "/home/exbot/code/python/tornado/Tjango/contrib/admin/log.py", line 21, in get_lastest_log_offset
    BaseHandler.prepare(self)
  File "/home/exbot/code/python/tornado/Tjango/contrib/admin/view.py", line 18, in prepare
    database.connect()
  File "/usr/local/lib/python2.7/dist-packages/peewee.py", line 3669, in connect
    raise OperationalError('Connection already open')
OperationalError: Connection already open
2017-05-13 18:34:01,074 - tornado.application - ERROR - Exception in callback <function praseLog at 0x7ff15b1f7578>
Traceback (most recent call last):
  File "/usr/local/lib/python2.7/dist-packages/tornado/ioloop.py", line 1026, in _run
    return self.callback()
  File "/home/exbot/code/python/tornado/Tjango/contrib/admin/log.py", line 94, in praseLog
    a.parase_log()
  File "/home/exbot/code/python/tornado/Tjango/contrib/admin/log.py", line 33, in parase_log
    latest_log_offset = self.get_lastest_log_offset()
  File "/home/exbot/code/python/tornado/Tjango/contrib/admin/log.py", line 21, in get_lastest_log_offset
    BaseHandler.prepare(self)
  File "/home/exbot/code/python/tornado/Tjango/contrib/admin/view.py", line 18, in prepare
    database.connect()
  File "/usr/local/lib/python2.7/dist-packages/peewee.py", line 3669, in connect
    raise OperationalError('Connection already open')
OperationalError: Connection already open
2017-05-13 18:44:01,138 - tornado.application - ERROR - Exception in callback <function praseLog at 0x7ff15b1f7578>
Traceback (most recent call last):
  File "/usr/local/lib/python2.7/dist-packages/tornado/ioloop.py", line 1026, in _run
    return self.callback()
  File "/home/exbot/code/python/tornado/Tjango/contrib/admin/log.py", line 94, in praseLog
    a.parase_log()
  File "/home/exbot/code/python/tornado/Tjango/contrib/admin/log.py", line 33, in parase_log
    latest_log_offset = self.get_lastest_log_offset()
  File "/home/exbot/code/python/tornado/Tjango/contrib/admin/log.py", line 21, in get_lastest_log_offset
    BaseHandler.prepare(self)
  File "/home/exbot/code/python/tornado/Tjango/contrib/admin/view.py", line 18, in prepare
    database.connect()
  File "/usr/local/lib/python2.7/dist-packages/peewee.py", line 3669, in connect
    raise OperationalError('Connection already open')
OperationalError: Connection already open
2017-05-13 18:54:01,138 - tornado.application - ERROR - Exception in callback <function praseLog at 0x7ff15b1f7578>
Traceback (most recent call last):
  File "/usr/local/lib/python2.7/dist-packages/tornado/ioloop.py", line 1026, in _run
    return self.callback()
  File "/home/exbot/code/python/tornado/Tjango/contrib/admin/log.py", line 94, in praseLog
    a.parase_log()
  File "/home/exbot/code/python/tornado/Tjango/contrib/admin/log.py", line 33, in parase_log
    latest_log_offset = self.get_lastest_log_offset()
  File "/home/exbot/code/python/tornado/Tjango/contrib/admin/log.py", line 21, in get_lastest_log_offset
    BaseHandler.prepare(self)
  File "/home/exbot/code/python/tornado/Tjango/contrib/admin/view.py", line 18, in prepare
    database.connect()
  File "/usr/local/lib/python2.7/dist-packages/peewee.py", line 3669, in connect
    raise OperationalError('Connection already open')
OperationalError: Connection already open
2017-05-13 19:04:01,148 - tornado.application - ERROR - Exception in callback <function praseLog at 0x7ff15b1f7578>
Traceback (most recent call last):
  File "/usr/local/lib/python2.7/dist-packages/tornado/ioloop.py", line 1026, in _run
    return self.callback()
  File "/home/exbot/code/python/tornado/Tjango/contrib/admin/log.py", line 94, in praseLog
    a.parase_log()
  File "/home/exbot/code/python/tornado/Tjango/contrib/admin/log.py", line 33, in parase_log
    latest_log_offset = self.get_lastest_log_offset()
  File "/home/exbot/code/python/tornado/Tjango/contrib/admin/log.py", line 21, in get_lastest_log_offset
    BaseHandler.prepare(self)
  File "/home/exbot/code/python/tornado/Tjango/contrib/admin/view.py", line 18, in prepare
    database.connect()
  File "/usr/local/lib/python2.7/dist-packages/peewee.py", line 3669, in connect
    raise OperationalError('Connection already open')
OperationalError: Connection already open
2017-05-13 19:14:01,145 - tornado.application - ERROR - Exception in callback <function praseLog at 0x7ff15b1f7578>
Traceback (most recent call last):
  File "/usr/local/lib/python2.7/dist-packages/tornado/ioloop.py", line 1026, in _run
    return self.callback()
  File "/home/exbot/code/python/tornado/Tjango/contrib/admin/log.py", line 94, in praseLog
    a.parase_log()
  File "/home/exbot/code/python/tornado/Tjango/contrib/admin/log.py", line 33, in parase_log
    latest_log_offset = self.get_lastest_log_offset()
  File "/home/exbot/code/python/tornado/Tjango/contrib/admin/log.py", line 21, in get_lastest_log_offset
    BaseHandler.prepare(self)
  File "/home/exbot/code/python/tornado/Tjango/contrib/admin/view.py", line 18, in prepare
    database.connect()
  File "/usr/local/lib/python2.7/dist-packages/peewee.py", line 3669, in connect
    raise OperationalError('Connection already open')
OperationalError: Connection already open
2017-05-13 19:24:01,084 - tornado.application - ERROR - Exception in callback <function praseLog at 0x7ff15b1f7578>
Traceback (most recent call last):
  File "/usr/local/lib/python2.7/dist-packages/tornado/ioloop.py", line 1026, in _run
    return self.callback()
  File "/home/exbot/code/python/tornado/Tjango/contrib/admin/log.py", line 94, in praseLog
    a.parase_log()
  File "/home/exbot/code/python/tornado/Tjango/contrib/admin/log.py", line 33, in parase_log
    latest_log_offset = self.get_lastest_log_offset()
  File "/home/exbot/code/python/tornado/Tjango/contrib/admin/log.py", line 21, in get_lastest_log_offset
    BaseHandler.prepare(self)
  File "/home/exbot/code/python/tornado/Tjango/contrib/admin/view.py", line 18, in prepare
    database.connect()
  File "/usr/local/lib/python2.7/dist-packages/peewee.py", line 3669, in connect
    raise OperationalError('Connection already open')
OperationalError: Connection already open
2017-05-13 19:34:01,145 - tornado.application - ERROR - Exception in callback <function praseLog at 0x7ff15b1f7578>
Traceback (most recent call last):
  File "/usr/local/lib/python2.7/dist-packages/tornado/ioloop.py", line 1026, in _run
    return self.callback()
  File "/home/exbot/code/python/tornado/Tjango/contrib/admin/log.py", line 94, in praseLog
    a.parase_log()
  File "/home/exbot/code/python/tornado/Tjango/contrib/admin/log.py", line 33, in parase_log
    latest_log_offset = self.get_lastest_log_offset()
  File "/home/exbot/code/python/tornado/Tjango/contrib/admin/log.py", line 21, in get_lastest_log_offset
    BaseHandler.prepare(self)
  File "/home/exbot/code/python/tornado/Tjango/contrib/admin/view.py", line 18, in prepare
    database.connect()
  File "/usr/local/lib/python2.7/dist-packages/peewee.py", line 3669, in connect
    raise OperationalError('Connection already open')
OperationalError: Connection already open
2017-05-13 19:44:01,150 - tornado.application - ERROR - Exception in callback <function praseLog at 0x7ff15b1f7578>
Traceback (most recent call last):
  File "/usr/local/lib/python2.7/dist-packages/tornado/ioloop.py", line 1026, in _run
    return self.callback()
  File "/home/exbot/code/python/tornado/Tjango/contrib/admin/log.py", line 94, in praseLog
    a.parase_log()
  File "/home/exbot/code/python/tornado/Tjango/contrib/admin/log.py", line 33, in parase_log
    latest_log_offset = self.get_lastest_log_offset()
  File "/home/exbot/code/python/tornado/Tjango/contrib/admin/log.py", line 21, in get_lastest_log_offset
    BaseHandler.prepare(self)
  File "/home/exbot/code/python/tornado/Tjango/contrib/admin/view.py", line 18, in prepare
    database.connect()
  File "/usr/local/lib/python2.7/dist-packages/peewee.py", line 3669, in connect
    raise OperationalError('Connection already open')
OperationalError: Connection already open
2017-05-13 19:54:01,068 - tornado.application - ERROR - Exception in callback <function praseLog at 0x7ff15b1f7578>
Traceback (most recent call last):
  File "/usr/local/lib/python2.7/dist-packages/tornado/ioloop.py", line 1026, in _run
    return self.callback()
  File "/home/exbot/code/python/tornado/Tjango/contrib/admin/log.py", line 94, in praseLog
    a.parase_log()
  File "/home/exbot/code/python/tornado/Tjango/contrib/admin/log.py", line 33, in parase_log
    latest_log_offset = self.get_lastest_log_offset()
  File "/home/exbot/code/python/tornado/Tjango/contrib/admin/log.py", line 21, in get_lastest_log_offset
    BaseHandler.prepare(self)
  File "/home/exbot/code/python/tornado/Tjango/contrib/admin/view.py", line 18, in prepare
    database.connect()
  File "/usr/local/lib/python2.7/dist-packages/peewee.py", line 3669, in connect
    raise OperationalError('Connection already open')
OperationalError: Connection already open
2017-05-13 20:04:01,143 - tornado.application - ERROR - Exception in callback <function praseLog at 0x7ff15b1f7578>
Traceback (most recent call last):
  File "/usr/local/lib/python2.7/dist-packages/tornado/ioloop.py", line 1026, in _run
    return self.callback()
  File "/home/exbot/code/python/tornado/Tjango/contrib/admin/log.py", line 94, in praseLog
    a.parase_log()
  File "/home/exbot/code/python/tornado/Tjango/contrib/admin/log.py", line 33, in parase_log
    latest_log_offset = self.get_lastest_log_offset()
  File "/home/exbot/code/python/tornado/Tjango/contrib/admin/log.py", line 21, in get_lastest_log_offset
    BaseHandler.prepare(self)
  File "/home/exbot/code/python/tornado/Tjango/contrib/admin/view.py", line 18, in prepare
    database.connect()
  File "/usr/local/lib/python2.7/dist-packages/peewee.py", line 3669, in connect
    raise OperationalError('Connection already open')
OperationalError: Connection already open
2017-05-13 20:14:01,118 - tornado.application - ERROR - Exception in callback <function praseLog at 0x7ff15b1f7578>
Traceback (most recent call last):
  File "/usr/local/lib/python2.7/dist-packages/tornado/ioloop.py", line 1026, in _run
    return self.callback()
  File "/home/exbot/code/python/tornado/Tjango/contrib/admin/log.py", line 94, in praseLog
    a.parase_log()
  File "/home/exbot/code/python/tornado/Tjango/contrib/admin/log.py", line 33, in parase_log
    latest_log_offset = self.get_lastest_log_offset()
  File "/home/exbot/code/python/tornado/Tjango/contrib/admin/log.py", line 21, in get_lastest_log_offset
    BaseHandler.prepare(self)
  File "/home/exbot/code/python/tornado/Tjango/contrib/admin/view.py", line 18, in prepare
    database.connect()
  File "/usr/local/lib/python2.7/dist-packages/peewee.py", line 3669, in connect
    raise OperationalError('Connection already open')
OperationalError: Connection already open
2017-05-13 20:24:01,150 - tornado.application - ERROR - Exception in callback <function praseLog at 0x7ff15b1f7578>
Traceback (most recent call last):
  File "/usr/local/lib/python2.7/dist-packages/tornado/ioloop.py", line 1026, in _run
    return self.callback()
  File "/home/exbot/code/python/tornado/Tjango/contrib/admin/log.py", line 94, in praseLog
    a.parase_log()
  File "/home/exbot/code/python/tornado/Tjango/contrib/admin/log.py", line 33, in parase_log
    latest_log_offset = self.get_lastest_log_offset()
  File "/home/exbot/code/python/tornado/Tjango/contrib/admin/log.py", line 21, in get_lastest_log_offset
    BaseHandler.prepare(self)
  File "/home/exbot/code/python/tornado/Tjango/contrib/admin/view.py", line 18, in prepare
    database.connect()
  File "/usr/local/lib/python2.7/dist-packages/peewee.py", line 3669, in connect
    raise OperationalError('Connection already open')
OperationalError: Connection already open
2017-05-13 20:34:01,139 - tornado.application - ERROR - Exception in callback <function praseLog at 0x7ff15b1f7578>
Traceback (most recent call last):
  File "/usr/local/lib/python2.7/dist-packages/tornado/ioloop.py", line 1026, in _run
    return self.callback()
  File "/home/exbot/code/python/tornado/Tjango/contrib/admin/log.py", line 94, in praseLog
    a.parase_log()
  File "/home/exbot/code/python/tornado/Tjango/contrib/admin/log.py", line 33, in parase_log
    latest_log_offset = self.get_lastest_log_offset()
  File "/home/exbot/code/python/tornado/Tjango/contrib/admin/log.py", line 21, in get_lastest_log_offset
    BaseHandler.prepare(self)
  File "/home/exbot/code/python/tornado/Tjango/contrib/admin/view.py", line 18, in prepare
    database.connect()
  File "/usr/local/lib/python2.7/dist-packages/peewee.py", line 3669, in connect
    raise OperationalError('Connection already open')
OperationalError: Connection already open
2017-05-13 20:44:01,150 - tornado.application - ERROR - Exception in callback <function praseLog at 0x7ff15b1f7578>
Traceback (most recent call last):
  File "/usr/local/lib/python2.7/dist-packages/tornado/ioloop.py", line 1026, in _run
    return self.callback()
  File "/home/exbot/code/python/tornado/Tjango/contrib/admin/log.py", line 94, in praseLog
    a.parase_log()
  File "/home/exbot/code/python/tornado/Tjango/contrib/admin/log.py", line 33, in parase_log
    latest_log_offset = self.get_lastest_log_offset()
  File "/home/exbot/code/python/tornado/Tjango/contrib/admin/log.py", line 21, in get_lastest_log_offset
    BaseHandler.prepare(self)
  File "/home/exbot/code/python/tornado/Tjango/contrib/admin/view.py", line 18, in prepare
    database.connect()
  File "/usr/local/lib/python2.7/dist-packages/peewee.py", line 3669, in connect
    raise OperationalError('Connection already open')
OperationalError: Connection already open
2017-05-13 20:54:01,084 - tornado.application - ERROR - Exception in callback <function praseLog at 0x7ff15b1f7578>
Traceback (most recent call last):
  File "/usr/local/lib/python2.7/dist-packages/tornado/ioloop.py", line 1026, in _run
    return self.callback()
  File "/home/exbot/code/python/tornado/Tjango/contrib/admin/log.py", line 94, in praseLog
    a.parase_log()
  File "/home/exbot/code/python/tornado/Tjango/contrib/admin/log.py", line 33, in parase_log
    latest_log_offset = self.get_lastest_log_offset()
  File "/home/exbot/code/python/tornado/Tjango/contrib/admin/log.py", line 21, in get_lastest_log_offset
    BaseHandler.prepare(self)
  File "/home/exbot/code/python/tornado/Tjango/contrib/admin/view.py", line 18, in prepare
    database.connect()
  File "/usr/local/lib/python2.7/dist-packages/peewee.py", line 3669, in connect
    raise OperationalError('Connection already open')
OperationalError: Connection already open
2017-05-13 21:04:01,135 - tornado.application - ERROR - Exception in callback <function praseLog at 0x7ff15b1f7578>
Traceback (most recent call last):
  File "/usr/local/lib/python2.7/dist-packages/tornado/ioloop.py", line 1026, in _run
    return self.callback()
  File "/home/exbot/code/python/tornado/Tjango/contrib/admin/log.py", line 94, in praseLog
    a.parase_log()
  File "/home/exbot/code/python/tornado/Tjango/contrib/admin/log.py", line 33, in parase_log
    latest_log_offset = self.get_lastest_log_offset()
  File "/home/exbot/code/python/tornado/Tjango/contrib/admin/log.py", line 21, in get_lastest_log_offset
    BaseHandler.prepare(self)
  File "/home/exbot/code/python/tornado/Tjango/contrib/admin/view.py", line 18, in prepare
    database.connect()
  File "/usr/local/lib/python2.7/dist-packages/peewee.py", line 3669, in connect
    raise OperationalError('Connection already open')
OperationalError: Connection already open
2017-05-13 21:14:01,148 - tornado.application - ERROR - Exception in callback <function praseLog at 0x7ff15b1f7578>
Traceback (most recent call last):
  File "/usr/local/lib/python2.7/dist-packages/tornado/ioloop.py", line 1026, in _run
    return self.callback()
  File "/home/exbot/code/python/tornado/Tjango/contrib/admin/log.py", line 94, in praseLog
    a.parase_log()
  File "/home/exbot/code/python/tornado/Tjango/contrib/admin/log.py", line 33, in parase_log
    latest_log_offset = self.get_lastest_log_offset()
  File "/home/exbot/code/python/tornado/Tjango/contrib/admin/log.py", line 21, in get_lastest_log_offset
    BaseHandler.prepare(self)
  File "/home/exbot/code/python/tornado/Tjango/contrib/admin/view.py", line 18, in prepare
    database.connect()
  File "/usr/local/lib/python2.7/dist-packages/peewee.py", line 3669, in connect
    raise OperationalError('Connection already open')
OperationalError: Connection already open
2017-05-13 21:24:01,139 - tornado.application - ERROR - Exception in callback <function praseLog at 0x7ff15b1f7578>
Traceback (most recent call last):
  File "/usr/local/lib/python2.7/dist-packages/tornado/ioloop.py", line 1026, in _run
    return self.callback()
  File "/home/exbot/code/python/tornado/Tjango/contrib/admin/log.py", line 94, in praseLog
    a.parase_log()
  File "/home/exbot/code/python/tornado/Tjango/contrib/admin/log.py", line 33, in parase_log
    latest_log_offset = self.get_lastest_log_offset()
  File "/home/exbot/code/python/tornado/Tjango/contrib/admin/log.py", line 21, in get_lastest_log_offset
    BaseHandler.prepare(self)
  File "/home/exbot/code/python/tornado/Tjango/contrib/admin/view.py", line 18, in prepare
    database.connect()
  File "/usr/local/lib/python2.7/dist-packages/peewee.py", line 3669, in connect
    raise OperationalError('Connection already open')
OperationalError: Connection already open
2017-05-13 21:34:01,143 - tornado.application - ERROR - Exception in callback <function praseLog at 0x7ff15b1f7578>
Traceback (most recent call last):
  File "/usr/local/lib/python2.7/dist-packages/tornado/ioloop.py", line 1026, in _run
    return self.callback()
  File "/home/exbot/code/python/tornado/Tjango/contrib/admin/log.py", line 94, in praseLog
    a.parase_log()
  File "/home/exbot/code/python/tornado/Tjango/contrib/admin/log.py", line 33, in parase_log
    latest_log_offset = self.get_lastest_log_offset()
  File "/home/exbot/code/python/tornado/Tjango/contrib/admin/log.py", line 21, in get_lastest_log_offset
    BaseHandler.prepare(self)
  File "/home/exbot/code/python/tornado/Tjango/contrib/admin/view.py", line 18, in prepare
    database.connect()
  File "/usr/local/lib/python2.7/dist-packages/peewee.py", line 3669, in connect
    raise OperationalError('Connection already open')
OperationalError: Connection already open
2017-05-13 21:44:01,109 - tornado.application - ERROR - Exception in callback <function praseLog at 0x7ff15b1f7578>
Traceback (most recent call last):
  File "/usr/local/lib/python2.7/dist-packages/tornado/ioloop.py", line 1026, in _run
    return self.callback()
  File "/home/exbot/code/python/tornado/Tjango/contrib/admin/log.py", line 94, in praseLog
    a.parase_log()
  File "/home/exbot/code/python/tornado/Tjango/contrib/admin/log.py", line 33, in parase_log
    latest_log_offset = self.get_lastest_log_offset()
  File "/home/exbot/code/python/tornado/Tjango/contrib/admin/log.py", line 21, in get_lastest_log_offset
    BaseHandler.prepare(self)
  File "/home/exbot/code/python/tornado/Tjango/contrib/admin/view.py", line 18, in prepare
    database.connect()
  File "/usr/local/lib/python2.7/dist-packages/peewee.py", line 3669, in connect
    raise OperationalError('Connection already open')
OperationalError: Connection already open
2017-05-13 21:54:01,077 - tornado.application - ERROR - Exception in callback <function praseLog at 0x7ff15b1f7578>
Traceback (most recent call last):
  File "/usr/local/lib/python2.7/dist-packages/tornado/ioloop.py", line 1026, in _run
    return self.callback()
  File "/home/exbot/code/python/tornado/Tjango/contrib/admin/log.py", line 94, in praseLog
    a.parase_log()
  File "/home/exbot/code/python/tornado/Tjango/contrib/admin/log.py", line 33, in parase_log
    latest_log_offset = self.get_lastest_log_offset()
  File "/home/exbot/code/python/tornado/Tjango/contrib/admin/log.py", line 21, in get_lastest_log_offset
    BaseHandler.prepare(self)
  File "/home/exbot/code/python/tornado/Tjango/contrib/admin/view.py", line 18, in prepare
    database.connect()
  File "/usr/local/lib/python2.7/dist-packages/peewee.py", line 3669, in connect
    raise OperationalError('Connection already open')
OperationalError: Connection already open
2017-05-13 22:04:01,063 - tornado.application - ERROR - Exception in callback <function praseLog at 0x7ff15b1f7578>
Traceback (most recent call last):
  File "/usr/local/lib/python2.7/dist-packages/tornado/ioloop.py", line 1026, in _run
    return self.callback()
  File "/home/exbot/code/python/tornado/Tjango/contrib/admin/log.py", line 94, in praseLog
    a.parase_log()
  File "/home/exbot/code/python/tornado/Tjango/contrib/admin/log.py", line 33, in parase_log
    latest_log_offset = self.get_lastest_log_offset()
  File "/home/exbot/code/python/tornado/Tjango/contrib/admin/log.py", line 21, in get_lastest_log_offset
    BaseHandler.prepare(self)
  File "/home/exbot/code/python/tornado/Tjango/contrib/admin/view.py", line 18, in prepare
    database.connect()
  File "/usr/local/lib/python2.7/dist-packages/peewee.py", line 3669, in connect
    raise OperationalError('Connection already open')
OperationalError: Connection already open
2017-05-13 22:14:01,148 - tornado.application - ERROR - Exception in callback <function praseLog at 0x7ff15b1f7578>
Traceback (most recent call last):
  File "/usr/local/lib/python2.7/dist-packages/tornado/ioloop.py", line 1026, in _run
    return self.callback()
  File "/home/exbot/code/python/tornado/Tjango/contrib/admin/log.py", line 94, in praseLog
    a.parase_log()
  File "/home/exbot/code/python/tornado/Tjango/contrib/admin/log.py", line 33, in parase_log
    latest_log_offset = self.get_lastest_log_offset()
  File "/home/exbot/code/python/tornado/Tjango/contrib/admin/log.py", line 21, in get_lastest_log_offset
    BaseHandler.prepare(self)
  File "/home/exbot/code/python/tornado/Tjango/contrib/admin/view.py", line 18, in prepare
    database.connect()
  File "/usr/local/lib/python2.7/dist-packages/peewee.py", line 3669, in connect
    raise OperationalError('Connection already open')
OperationalError: Connection already open
2017-05-13 22:24:01,079 - tornado.application - ERROR - Exception in callback <function praseLog at 0x7ff15b1f7578>
Traceback (most recent call last):
  File "/usr/local/lib/python2.7/dist-packages/tornado/ioloop.py", line 1026, in _run
    return self.callback()
  File "/home/exbot/code/python/tornado/Tjango/contrib/admin/log.py", line 94, in praseLog
    a.parase_log()
  File "/home/exbot/code/python/tornado/Tjango/contrib/admin/log.py", line 33, in parase_log
    latest_log_offset = self.get_lastest_log_offset()
  File "/home/exbot/code/python/tornado/Tjango/contrib/admin/log.py", line 21, in get_lastest_log_offset
    BaseHandler.prepare(self)
  File "/home/exbot/code/python/tornado/Tjango/contrib/admin/view.py", line 18, in prepare
    database.connect()
  File "/usr/local/lib/python2.7/dist-packages/peewee.py", line 3669, in connect
    raise OperationalError('Connection already open')
OperationalError: Connection already open
2017-05-13 22:34:01,078 - tornado.application - ERROR - Exception in callback <function praseLog at 0x7ff15b1f7578>
Traceback (most recent call last):
  File "/usr/local/lib/python2.7/dist-packages/tornado/ioloop.py", line 1026, in _run
    return self.callback()
  File "/home/exbot/code/python/tornado/Tjango/contrib/admin/log.py", line 94, in praseLog
    a.parase_log()
  File "/home/exbot/code/python/tornado/Tjango/contrib/admin/log.py", line 33, in parase_log
    latest_log_offset = self.get_lastest_log_offset()
  File "/home/exbot/code/python/tornado/Tjango/contrib/admin/log.py", line 21, in get_lastest_log_offset
    BaseHandler.prepare(self)
  File "/home/exbot/code/python/tornado/Tjango/contrib/admin/view.py", line 18, in prepare
    database.connect()
  File "/usr/local/lib/python2.7/dist-packages/peewee.py", line 3669, in connect
    raise OperationalError('Connection already open')
OperationalError: Connection already open
2017-05-13 22:44:01,102 - tornado.application - ERROR - Exception in callback <function praseLog at 0x7ff15b1f7578>
Traceback (most recent call last):
  File "/usr/local/lib/python2.7/dist-packages/tornado/ioloop.py", line 1026, in _run
    return self.callback()
  File "/home/exbot/code/python/tornado/Tjango/contrib/admin/log.py", line 94, in praseLog
    a.parase_log()
  File "/home/exbot/code/python/tornado/Tjango/contrib/admin/log.py", line 33, in parase_log
    latest_log_offset = self.get_lastest_log_offset()
  File "/home/exbot/code/python/tornado/Tjango/contrib/admin/log.py", line 21, in get_lastest_log_offset
    BaseHandler.prepare(self)
  File "/home/exbot/code/python/tornado/Tjango/contrib/admin/view.py", line 18, in prepare
    database.connect()
  File "/usr/local/lib/python2.7/dist-packages/peewee.py", line 3669, in connect
    raise OperationalError('Connection already open')
OperationalError: Connection already open
2017-05-13 22:54:01,142 - tornado.application - ERROR - Exception in callback <function praseLog at 0x7ff15b1f7578>
Traceback (most recent call last):
  File "/usr/local/lib/python2.7/dist-packages/tornado/ioloop.py", line 1026, in _run
    return self.callback()
  File "/home/exbot/code/python/tornado/Tjango/contrib/admin/log.py", line 94, in praseLog
    a.parase_log()
  File "/home/exbot/code/python/tornado/Tjango/contrib/admin/log.py", line 33, in parase_log
    latest_log_offset = self.get_lastest_log_offset()
  File "/home/exbot/code/python/tornado/Tjango/contrib/admin/log.py", line 21, in get_lastest_log_offset
    BaseHandler.prepare(self)
  File "/home/exbot/code/python/tornado/Tjango/contrib/admin/view.py", line 18, in prepare
    database.connect()
  File "/usr/local/lib/python2.7/dist-packages/peewee.py", line 3669, in connect
    raise OperationalError('Connection already open')
OperationalError: Connection already open
2017-05-13 23:04:01,132 - tornado.application - ERROR - Exception in callback <function praseLog at 0x7ff15b1f7578>
Traceback (most recent call last):
  File "/usr/local/lib/python2.7/dist-packages/tornado/ioloop.py", line 1026, in _run
    return self.callback()
  File "/home/exbot/code/python/tornado/Tjango/contrib/admin/log.py", line 94, in praseLog
    a.parase_log()
  File "/home/exbot/code/python/tornado/Tjango/contrib/admin/log.py", line 33, in parase_log
    latest_log_offset = self.get_lastest_log_offset()
  File "/home/exbot/code/python/tornado/Tjango/contrib/admin/log.py", line 21, in get_lastest_log_offset
    BaseHandler.prepare(self)
  File "/home/exbot/code/python/tornado/Tjango/contrib/admin/view.py", line 18, in prepare
    database.connect()
  File "/usr/local/lib/python2.7/dist-packages/peewee.py", line 3669, in connect
    raise OperationalError('Connection already open')
OperationalError: Connection already open
2017-05-13 23:14:01,093 - tornado.application - ERROR - Exception in callback <function praseLog at 0x7ff15b1f7578>
Traceback (most recent call last):
  File "/usr/local/lib/python2.7/dist-packages/tornado/ioloop.py", line 1026, in _run
    return self.callback()
  File "/home/exbot/code/python/tornado/Tjango/contrib/admin/log.py", line 94, in praseLog
    a.parase_log()
  File "/home/exbot/code/python/tornado/Tjango/contrib/admin/log.py", line 33, in parase_log
    latest_log_offset = self.get_lastest_log_offset()
  File "/home/exbot/code/python/tornado/Tjango/contrib/admin/log.py", line 21, in get_lastest_log_offset
    BaseHandler.prepare(self)
  File "/home/exbot/code/python/tornado/Tjango/contrib/admin/view.py", line 18, in prepare
    database.connect()
  File "/usr/local/lib/python2.7/dist-packages/peewee.py", line 3669, in connect
    raise OperationalError('Connection already open')
OperationalError: Connection already open
2017-05-13 23:24:01,097 - tornado.application - ERROR - Exception in callback <function praseLog at 0x7ff15b1f7578>
Traceback (most recent call last):
  File "/usr/local/lib/python2.7/dist-packages/tornado/ioloop.py", line 1026, in _run
    return self.callback()
  File "/home/exbot/code/python/tornado/Tjango/contrib/admin/log.py", line 94, in praseLog
    a.parase_log()
  File "/home/exbot/code/python/tornado/Tjango/contrib/admin/log.py", line 33, in parase_log
    latest_log_offset = self.get_lastest_log_offset()
  File "/home/exbot/code/python/tornado/Tjango/contrib/admin/log.py", line 21, in get_lastest_log_offset
    BaseHandler.prepare(self)
  File "/home/exbot/code/python/tornado/Tjango/contrib/admin/view.py", line 18, in prepare
    database.connect()
  File "/usr/local/lib/python2.7/dist-packages/peewee.py", line 3669, in connect
    raise OperationalError('Connection already open')
OperationalError: Connection already open
2017-05-13 23:34:01,151 - tornado.application - ERROR - Exception in callback <function praseLog at 0x7ff15b1f7578>
Traceback (most recent call last):
  File "/usr/local/lib/python2.7/dist-packages/tornado/ioloop.py", line 1026, in _run
    return self.callback()
  File "/home/exbot/code/python/tornado/Tjango/contrib/admin/log.py", line 94, in praseLog
    a.parase_log()
  File "/home/exbot/code/python/tornado/Tjango/contrib/admin/log.py", line 33, in parase_log
    latest_log_offset = self.get_lastest_log_offset()
  File "/home/exbot/code/python/tornado/Tjango/contrib/admin/log.py", line 21, in get_lastest_log_offset
    BaseHandler.prepare(self)
  File "/home/exbot/code/python/tornado/Tjango/contrib/admin/view.py", line 18, in prepare
    database.connect()
  File "/usr/local/lib/python2.7/dist-packages/peewee.py", line 3669, in connect
    raise OperationalError('Connection already open')
OperationalError: Connection already open
2017-05-13 23:44:01,151 - tornado.application - ERROR - Exception in callback <function praseLog at 0x7ff15b1f7578>
Traceback (most recent call last):
  File "/usr/local/lib/python2.7/dist-packages/tornado/ioloop.py", line 1026, in _run
    return self.callback()
  File "/home/exbot/code/python/tornado/Tjango/contrib/admin/log.py", line 94, in praseLog
    a.parase_log()
  File "/home/exbot/code/python/tornado/Tjango/contrib/admin/log.py", line 33, in parase_log
    latest_log_offset = self.get_lastest_log_offset()
  File "/home/exbot/code/python/tornado/Tjango/contrib/admin/log.py", line 21, in get_lastest_log_offset
    BaseHandler.prepare(self)
  File "/home/exbot/code/python/tornado/Tjango/contrib/admin/view.py", line 18, in prepare
    database.connect()
  File "/usr/local/lib/python2.7/dist-packages/peewee.py", line 3669, in connect
    raise OperationalError('Connection already open')
OperationalError: Connection already open
2017-05-13 23:54:01,065 - tornado.application - ERROR - Exception in callback <function praseLog at 0x7ff15b1f7578>
Traceback (most recent call last):
  File "/usr/local/lib/python2.7/dist-packages/tornado/ioloop.py", line 1026, in _run
    return self.callback()
  File "/home/exbot/code/python/tornado/Tjango/contrib/admin/log.py", line 94, in praseLog
    a.parase_log()
  File "/home/exbot/code/python/tornado/Tjango/contrib/admin/log.py", line 33, in parase_log
    latest_log_offset = self.get_lastest_log_offset()
  File "/home/exbot/code/python/tornado/Tjango/contrib/admin/log.py", line 21, in get_lastest_log_offset
    BaseHandler.prepare(self)
  File "/home/exbot/code/python/tornado/Tjango/contrib/admin/view.py", line 18, in prepare
    database.connect()
  File "/usr/local/lib/python2.7/dist-packages/peewee.py", line 3669, in connect
    raise OperationalError('Connection already open')
OperationalError: Connection already open
