2017-05-12 12:51:57,164 - tornado.access - INFO - 200 GET / (::1) 320.56ms
2017-05-12 12:51:57,347 - tornado.access - INFO - 200 GET /static/image/police-beian/%E5%A4%87%E6%A1%88%E5%9B%BE%E6%A0%87.png?v=d0289dc0a46fc5b15b3363ffa78cf6c7 (::1) 42.90ms
2017-05-12 12:51:58,050 - tornado.access - WARNING - 404 GET /favicon.ico (::1) 26.90ms
2017-05-12 12:53:14,326 - tornado.access - INFO - 200 GET / (::1) 18.04ms
2017-05-12 12:53:34,237 - tornado.access - INFO - 200 GET / (::1) 30.45ms
2017-05-12 12:54:02,606 - tornado.access - INFO - 200 GET / (::1) 29.13ms
2017-05-12 13:04:01,056 - tornado.application - ERROR - Exception in callback <function praseLog at 0x7ff15b1f7578>
Traceback (most recent call last):
  File "/usr/local/lib/python2.7/dist-packages/tornado/ioloop.py", line 1026, in _run
    return self.callback()
  File "/home/exbot/code/python/tornado/Tjango/contrib/admin/log.py", line 94, in praseLog
    a.parase_log()
  File "/home/exbot/code/python/tornado/Tjango/contrib/admin/log.py", line 33, in parase_log
    latest_log_offset = self.get_lastest_log_offset()
  File "/home/exbot/code/python/tornado/Tjango/contrib/admin/log.py", line 21, in get_lastest_log_offset
    BaseHandler.prepare(self)
  File "/home/exbot/code/python/tornado/Tjango/contrib/admin/view.py", line 18, in prepare
    database.connect()
  File "/usr/local/lib/python2.7/dist-packages/peewee.py", line 3669, in connect
    raise OperationalError('Connection already open')
OperationalError: Connection already open
2017-05-12 13:14:01,113 - tornado.application - ERROR - Exception in callback <function praseLog at 0x7ff15b1f7578>
Traceback (most recent call last):
  File "/usr/local/lib/python2.7/dist-packages/tornado/ioloop.py", line 1026, in _run
    return self.callback()
  File "/home/exbot/code/python/tornado/Tjango/contrib/admin/log.py", line 94, in praseLog
    a.parase_log()
  File "/home/exbot/code/python/tornado/Tjango/contrib/admin/log.py", line 33, in parase_log
    latest_log_offset = self.get_lastest_log_offset()
  File "/home/exbot/code/python/tornado/Tjango/contrib/admin/log.py", line 21, in get_lastest_log_offset
    BaseHandler.prepare(self)
  File "/home/exbot/code/python/tornado/Tjango/contrib/admin/view.py", line 18, in prepare
    database.connect()
  File "/usr/local/lib/python2.7/dist-packages/peewee.py", line 3669, in connect
    raise OperationalError('Connection already open')
OperationalError: Connection already open
2017-05-12 13:24:01,138 - tornado.application - ERROR - Exception in callback <function praseLog at 0x7ff15b1f7578>
Traceback (most recent call last):
  File "/usr/local/lib/python2.7/dist-packages/tornado/ioloop.py", line 1026, in _run
    return self.callback()
  File "/home/exbot/code/python/tornado/Tjango/contrib/admin/log.py", line 94, in praseLog
    a.parase_log()
  File "/home/exbot/code/python/tornado/Tjango/contrib/admin/log.py", line 33, in parase_log
    latest_log_offset = self.get_lastest_log_offset()
  File "/home/exbot/code/python/tornado/Tjango/contrib/admin/log.py", line 21, in get_lastest_log_offset
    BaseHandler.prepare(self)
  File "/home/exbot/code/python/tornado/Tjango/contrib/admin/view.py", line 18, in prepare
    database.connect()
  File "/usr/local/lib/python2.7/dist-packages/peewee.py", line 3669, in connect
    raise OperationalError('Connection already open')
OperationalError: Connection already open
2017-05-12 13:34:01,150 - tornado.application - ERROR - Exception in callback <function praseLog at 0x7ff15b1f7578>
Traceback (most recent call last):
  File "/usr/local/lib/python2.7/dist-packages/tornado/ioloop.py", line 1026, in _run
    return self.callback()
  File "/home/exbot/code/python/tornado/Tjango/contrib/admin/log.py", line 94, in praseLog
    a.parase_log()
  File "/home/exbot/code/python/tornado/Tjango/contrib/admin/log.py", line 33, in parase_log
    latest_log_offset = self.get_lastest_log_offset()
  File "/home/exbot/code/python/tornado/Tjango/contrib/admin/log.py", line 21, in get_lastest_log_offset
    BaseHandler.prepare(self)
  File "/home/exbot/code/python/tornado/Tjango/contrib/admin/view.py", line 18, in prepare
    database.connect()
  File "/usr/local/lib/python2.7/dist-packages/peewee.py", line 3669, in connect
    raise OperationalError('Connection already open')
OperationalError: Connection already open
2017-05-12 13:44:01,150 - tornado.application - ERROR - Exception in callback <function praseLog at 0x7ff15b1f7578>
Traceback (most recent call last):
  File "/usr/local/lib/python2.7/dist-packages/tornado/ioloop.py", line 1026, in _run
    return self.callback()
  File "/home/exbot/code/python/tornado/Tjango/contrib/admin/log.py", line 94, in praseLog
    a.parase_log()
  File "/home/exbot/code/python/tornado/Tjango/contrib/admin/log.py", line 33, in parase_log
    latest_log_offset = self.get_lastest_log_offset()
  File "/home/exbot/code/python/tornado/Tjango/contrib/admin/log.py", line 21, in get_lastest_log_offset
    BaseHandler.prepare(self)
  File "/home/exbot/code/python/tornado/Tjango/contrib/admin/view.py", line 18, in prepare
    database.connect()
  File "/usr/local/lib/python2.7/dist-packages/peewee.py", line 3669, in connect
    raise OperationalError('Connection already open')
OperationalError: Connection already open
2017-05-12 13:54:01,095 - tornado.application - ERROR - Exception in callback <function praseLog at 0x7ff15b1f7578>
Traceback (most recent call last):
  File "/usr/local/lib/python2.7/dist-packages/tornado/ioloop.py", line 1026, in _run
    return self.callback()
  File "/home/exbot/code/python/tornado/Tjango/contrib/admin/log.py", line 94, in praseLog
    a.parase_log()
  File "/home/exbot/code/python/tornado/Tjango/contrib/admin/log.py", line 33, in parase_log
    latest_log_offset = self.get_lastest_log_offset()
  File "/home/exbot/code/python/tornado/Tjango/contrib/admin/log.py", line 21, in get_lastest_log_offset
    BaseHandler.prepare(self)
  File "/home/exbot/code/python/tornado/Tjango/contrib/admin/view.py", line 18, in prepare
    database.connect()
  File "/usr/local/lib/python2.7/dist-packages/peewee.py", line 3669, in connect
    raise OperationalError('Connection already open')
OperationalError: Connection already open
2017-05-12 14:04:01,150 - tornado.application - ERROR - Exception in callback <function praseLog at 0x7ff15b1f7578>
Traceback (most recent call last):
  File "/usr/local/lib/python2.7/dist-packages/tornado/ioloop.py", line 1026, in _run
    return self.callback()
  File "/home/exbot/code/python/tornado/Tjango/contrib/admin/log.py", line 94, in praseLog
    a.parase_log()
  File "/home/exbot/code/python/tornado/Tjango/contrib/admin/log.py", line 33, in parase_log
    latest_log_offset = self.get_lastest_log_offset()
  File "/home/exbot/code/python/tornado/Tjango/contrib/admin/log.py", line 21, in get_lastest_log_offset
    BaseHandler.prepare(self)
  File "/home/exbot/code/python/tornado/Tjango/contrib/admin/view.py", line 18, in prepare
    database.connect()
  File "/usr/local/lib/python2.7/dist-packages/peewee.py", line 3669, in connect
    raise OperationalError('Connection already open')
OperationalError: Connection already open
2017-05-12 14:14:01,062 - tornado.application - ERROR - Exception in callback <function praseLog at 0x7ff15b1f7578>
Traceback (most recent call last):
  File "/usr/local/lib/python2.7/dist-packages/tornado/ioloop.py", line 1026, in _run
    return self.callback()
  File "/home/exbot/code/python/tornado/Tjango/contrib/admin/log.py", line 94, in praseLog
    a.parase_log()
  File "/home/exbot/code/python/tornado/Tjango/contrib/admin/log.py", line 33, in parase_log
    latest_log_offset = self.get_lastest_log_offset()
  File "/home/exbot/code/python/tornado/Tjango/contrib/admin/log.py", line 21, in get_lastest_log_offset
    BaseHandler.prepare(self)
  File "/home/exbot/code/python/tornado/Tjango/contrib/admin/view.py", line 18, in prepare
    database.connect()
  File "/usr/local/lib/python2.7/dist-packages/peewee.py", line 3669, in connect
    raise OperationalError('Connection already open')
OperationalError: Connection already open
2017-05-12 14:24:01,118 - tornado.application - ERROR - Exception in callback <function praseLog at 0x7ff15b1f7578>
Traceback (most recent call last):
  File "/usr/local/lib/python2.7/dist-packages/tornado/ioloop.py", line 1026, in _run
    return self.callback()
  File "/home/exbot/code/python/tornado/Tjango/contrib/admin/log.py", line 94, in praseLog
    a.parase_log()
  File "/home/exbot/code/python/tornado/Tjango/contrib/admin/log.py", line 33, in parase_log
    latest_log_offset = self.get_lastest_log_offset()
  File "/home/exbot/code/python/tornado/Tjango/contrib/admin/log.py", line 21, in get_lastest_log_offset
    BaseHandler.prepare(self)
  File "/home/exbot/code/python/tornado/Tjango/contrib/admin/view.py", line 18, in prepare
    database.connect()
  File "/usr/local/lib/python2.7/dist-packages/peewee.py", line 3669, in connect
    raise OperationalError('Connection already open')
OperationalError: Connection already open
2017-05-12 14:34:01,107 - tornado.application - ERROR - Exception in callback <function praseLog at 0x7ff15b1f7578>
Traceback (most recent call last):
  File "/usr/local/lib/python2.7/dist-packages/tornado/ioloop.py", line 1026, in _run
    return self.callback()
  File "/home/exbot/code/python/tornado/Tjango/contrib/admin/log.py", line 94, in praseLog
    a.parase_log()
  File "/home/exbot/code/python/tornado/Tjango/contrib/admin/log.py", line 33, in parase_log
    latest_log_offset = self.get_lastest_log_offset()
  File "/home/exbot/code/python/tornado/Tjango/contrib/admin/log.py", line 21, in get_lastest_log_offset
    BaseHandler.prepare(self)
  File "/home/exbot/code/python/tornado/Tjango/contrib/admin/view.py", line 18, in prepare
    database.connect()
  File "/usr/local/lib/python2.7/dist-packages/peewee.py", line 3669, in connect
    raise OperationalError('Connection already open')
OperationalError: Connection already open
2017-05-12 14:44:01,094 - tornado.application - ERROR - Exception in callback <function praseLog at 0x7ff15b1f7578>
Traceback (most recent call last):
  File "/usr/local/lib/python2.7/dist-packages/tornado/ioloop.py", line 1026, in _run
    return self.callback()
  File "/home/exbot/code/python/tornado/Tjango/contrib/admin/log.py", line 94, in praseLog
    a.parase_log()
  File "/home/exbot/code/python/tornado/Tjango/contrib/admin/log.py", line 33, in parase_log
    latest_log_offset = self.get_lastest_log_offset()
  File "/home/exbot/code/python/tornado/Tjango/contrib/admin/log.py", line 21, in get_lastest_log_offset
    BaseHandler.prepare(self)
  File "/home/exbot/code/python/tornado/Tjango/contrib/admin/view.py", line 18, in prepare
    database.connect()
  File "/usr/local/lib/python2.7/dist-packages/peewee.py", line 3669, in connect
    raise OperationalError('Connection already open')
OperationalError: Connection already open
2017-05-12 14:54:01,118 - tornado.application - ERROR - Exception in callback <function praseLog at 0x7ff15b1f7578>
Traceback (most recent call last):
  File "/usr/local/lib/python2.7/dist-packages/tornado/ioloop.py", line 1026, in _run
    return self.callback()
  File "/home/exbot/code/python/tornado/Tjango/contrib/admin/log.py", line 94, in praseLog
    a.parase_log()
  File "/home/exbot/code/python/tornado/Tjango/contrib/admin/log.py", line 33, in parase_log
    latest_log_offset = self.get_lastest_log_offset()
  File "/home/exbot/code/python/tornado/Tjango/contrib/admin/log.py", line 21, in get_lastest_log_offset
    BaseHandler.prepare(self)
  File "/home/exbot/code/python/tornado/Tjango/contrib/admin/view.py", line 18, in prepare
    database.connect()
  File "/usr/local/lib/python2.7/dist-packages/peewee.py", line 3669, in connect
    raise OperationalError('Connection already open')
OperationalError: Connection already open
2017-05-12 15:04:01,134 - tornado.application - ERROR - Exception in callback <function praseLog at 0x7ff15b1f7578>
Traceback (most recent call last):
  File "/usr/local/lib/python2.7/dist-packages/tornado/ioloop.py", line 1026, in _run
    return self.callback()
  File "/home/exbot/code/python/tornado/Tjango/contrib/admin/log.py", line 94, in praseLog
    a.parase_log()
  File "/home/exbot/code/python/tornado/Tjango/contrib/admin/log.py", line 33, in parase_log
    latest_log_offset = self.get_lastest_log_offset()
  File "/home/exbot/code/python/tornado/Tjango/contrib/admin/log.py", line 21, in get_lastest_log_offset
    BaseHandler.prepare(self)
  File "/home/exbot/code/python/tornado/Tjango/contrib/admin/view.py", line 18, in prepare
    database.connect()
  File "/usr/local/lib/python2.7/dist-packages/peewee.py", line 3669, in connect
    raise OperationalError('Connection already open')
OperationalError: Connection already open
2017-05-12 15:14:01,140 - tornado.application - ERROR - Exception in callback <function praseLog at 0x7ff15b1f7578>
Traceback (most recent call last):
  File "/usr/local/lib/python2.7/dist-packages/tornado/ioloop.py", line 1026, in _run
    return self.callback()
  File "/home/exbot/code/python/tornado/Tjango/contrib/admin/log.py", line 94, in praseLog
    a.parase_log()
  File "/home/exbot/code/python/tornado/Tjango/contrib/admin/log.py", line 33, in parase_log
    latest_log_offset = self.get_lastest_log_offset()
  File "/home/exbot/code/python/tornado/Tjango/contrib/admin/log.py", line 21, in get_lastest_log_offset
    BaseHandler.prepare(self)
  File "/home/exbot/code/python/tornado/Tjango/contrib/admin/view.py", line 18, in prepare
    database.connect()
  File "/usr/local/lib/python2.7/dist-packages/peewee.py", line 3669, in connect
    raise OperationalError('Connection already open')
OperationalError: Connection already open
2017-05-12 15:24:01,139 - tornado.application - ERROR - Exception in callback <function praseLog at 0x7ff15b1f7578>
Traceback (most recent call last):
  File "/usr/local/lib/python2.7/dist-packages/tornado/ioloop.py", line 1026, in _run
    return self.callback()
  File "/home/exbot/code/python/tornado/Tjango/contrib/admin/log.py", line 94, in praseLog
    a.parase_log()
  File "/home/exbot/code/python/tornado/Tjango/contrib/admin/log.py", line 33, in parase_log
    latest_log_offset = self.get_lastest_log_offset()
  File "/home/exbot/code/python/tornado/Tjango/contrib/admin/log.py", line 21, in get_lastest_log_offset
    BaseHandler.prepare(self)
  File "/home/exbot/code/python/tornado/Tjango/contrib/admin/view.py", line 18, in prepare
    database.connect()
  File "/usr/local/lib/python2.7/dist-packages/peewee.py", line 3669, in connect
    raise OperationalError('Connection already open')
OperationalError: Connection already open
2017-05-12 15:34:01,145 - tornado.application - ERROR - Exception in callback <function praseLog at 0x7ff15b1f7578>
Traceback (most recent call last):
  File "/usr/local/lib/python2.7/dist-packages/tornado/ioloop.py", line 1026, in _run
    return self.callback()
  File "/home/exbot/code/python/tornado/Tjango/contrib/admin/log.py", line 94, in praseLog
    a.parase_log()
  File "/home/exbot/code/python/tornado/Tjango/contrib/admin/log.py", line 33, in parase_log
    latest_log_offset = self.get_lastest_log_offset()
  File "/home/exbot/code/python/tornado/Tjango/contrib/admin/log.py", line 21, in get_lastest_log_offset
    BaseHandler.prepare(self)
  File "/home/exbot/code/python/tornado/Tjango/contrib/admin/view.py", line 18, in prepare
    database.connect()
  File "/usr/local/lib/python2.7/dist-packages/peewee.py", line 3669, in connect
    raise OperationalError('Connection already open')
OperationalError: Connection already open
2017-05-12 15:44:01,099 - tornado.application - ERROR - Exception in callback <function praseLog at 0x7ff15b1f7578>
Traceback (most recent call last):
  File "/usr/local/lib/python2.7/dist-packages/tornado/ioloop.py", line 1026, in _run
    return self.callback()
  File "/home/exbot/code/python/tornado/Tjango/contrib/admin/log.py", line 94, in praseLog
    a.parase_log()
  File "/home/exbot/code/python/tornado/Tjango/contrib/admin/log.py", line 33, in parase_log
    latest_log_offset = self.get_lastest_log_offset()
  File "/home/exbot/code/python/tornado/Tjango/contrib/admin/log.py", line 21, in get_lastest_log_offset
    BaseHandler.prepare(self)
  File "/home/exbot/code/python/tornado/Tjango/contrib/admin/view.py", line 18, in prepare
    database.connect()
  File "/usr/local/lib/python2.7/dist-packages/peewee.py", line 3669, in connect
    raise OperationalError('Connection already open')
OperationalError: Connection already open
2017-05-12 15:54:01,148 - tornado.application - ERROR - Exception in callback <function praseLog at 0x7ff15b1f7578>
Traceback (most recent call last):
  File "/usr/local/lib/python2.7/dist-packages/tornado/ioloop.py", line 1026, in _run
    return self.callback()
  File "/home/exbot/code/python/tornado/Tjango/contrib/admin/log.py", line 94, in praseLog
    a.parase_log()
  File "/home/exbot/code/python/tornado/Tjango/contrib/admin/log.py", line 33, in parase_log
    latest_log_offset = self.get_lastest_log_offset()
  File "/home/exbot/code/python/tornado/Tjango/contrib/admin/log.py", line 21, in get_lastest_log_offset
    BaseHandler.prepare(self)
  File "/home/exbot/code/python/tornado/Tjango/contrib/admin/view.py", line 18, in prepare
    database.connect()
  File "/usr/local/lib/python2.7/dist-packages/peewee.py", line 3669, in connect
    raise OperationalError('Connection already open')
OperationalError: Connection already open
2017-05-12 16:04:01,144 - tornado.application - ERROR - Exception in callback <function praseLog at 0x7ff15b1f7578>
Traceback (most recent call last):
  File "/usr/local/lib/python2.7/dist-packages/tornado/ioloop.py", line 1026, in _run
    return self.callback()
  File "/home/exbot/code/python/tornado/Tjango/contrib/admin/log.py", line 94, in praseLog
    a.parase_log()
  File "/home/exbot/code/python/tornado/Tjango/contrib/admin/log.py", line 33, in parase_log
    latest_log_offset = self.get_lastest_log_offset()
  File "/home/exbot/code/python/tornado/Tjango/contrib/admin/log.py", line 21, in get_lastest_log_offset
    BaseHandler.prepare(self)
  File "/home/exbot/code/python/tornado/Tjango/contrib/admin/view.py", line 18, in prepare
    database.connect()
  File "/usr/local/lib/python2.7/dist-packages/peewee.py", line 3669, in connect
    raise OperationalError('Connection already open')
OperationalError: Connection already open
2017-05-12 16:14:01,097 - tornado.application - ERROR - Exception in callback <function praseLog at 0x7ff15b1f7578>
Traceback (most recent call last):
  File "/usr/local/lib/python2.7/dist-packages/tornado/ioloop.py", line 1026, in _run
    return self.callback()
  File "/home/exbot/code/python/tornado/Tjango/contrib/admin/log.py", line 94, in praseLog
    a.parase_log()
  File "/home/exbot/code/python/tornado/Tjango/contrib/admin/log.py", line 33, in parase_log
    latest_log_offset = self.get_lastest_log_offset()
  File "/home/exbot/code/python/tornado/Tjango/contrib/admin/log.py", line 21, in get_lastest_log_offset
    BaseHandler.prepare(self)
  File "/home/exbot/code/python/tornado/Tjango/contrib/admin/view.py", line 18, in prepare
    database.connect()
  File "/usr/local/lib/python2.7/dist-packages/peewee.py", line 3669, in connect
    raise OperationalError('Connection already open')
OperationalError: Connection already open
2017-05-12 16:24:01,139 - tornado.application - ERROR - Exception in callback <function praseLog at 0x7ff15b1f7578>
Traceback (most recent call last):
  File "/usr/local/lib/python2.7/dist-packages/tornado/ioloop.py", line 1026, in _run
    return self.callback()
  File "/home/exbot/code/python/tornado/Tjango/contrib/admin/log.py", line 94, in praseLog
    a.parase_log()
  File "/home/exbot/code/python/tornado/Tjango/contrib/admin/log.py", line 33, in parase_log
    latest_log_offset = self.get_lastest_log_offset()
  File "/home/exbot/code/python/tornado/Tjango/contrib/admin/log.py", line 21, in get_lastest_log_offset
    BaseHandler.prepare(self)
  File "/home/exbot/code/python/tornado/Tjango/contrib/admin/view.py", line 18, in prepare
    database.connect()
  File "/usr/local/lib/python2.7/dist-packages/peewee.py", line 3669, in connect
    raise OperationalError('Connection already open')
OperationalError: Connection already open
2017-05-12 16:34:01,100 - tornado.application - ERROR - Exception in callback <function praseLog at 0x7ff15b1f7578>
Traceback (most recent call last):
  File "/usr/local/lib/python2.7/dist-packages/tornado/ioloop.py", line 1026, in _run
    return self.callback()
  File "/home/exbot/code/python/tornado/Tjango/contrib/admin/log.py", line 94, in praseLog
    a.parase_log()
  File "/home/exbot/code/python/tornado/Tjango/contrib/admin/log.py", line 33, in parase_log
    latest_log_offset = self.get_lastest_log_offset()
  File "/home/exbot/code/python/tornado/Tjango/contrib/admin/log.py", line 21, in get_lastest_log_offset
    BaseHandler.prepare(self)
  File "/home/exbot/code/python/tornado/Tjango/contrib/admin/view.py", line 18, in prepare
    database.connect()
  File "/usr/local/lib/python2.7/dist-packages/peewee.py", line 3669, in connect
    raise OperationalError('Connection already open')
OperationalError: Connection already open
2017-05-12 16:44:01,133 - tornado.application - ERROR - Exception in callback <function praseLog at 0x7ff15b1f7578>
Traceback (most recent call last):
  File "/usr/local/lib/python2.7/dist-packages/tornado/ioloop.py", line 1026, in _run
    return self.callback()
  File "/home/exbot/code/python/tornado/Tjango/contrib/admin/log.py", line 94, in praseLog
    a.parase_log()
  File "/home/exbot/code/python/tornado/Tjango/contrib/admin/log.py", line 33, in parase_log
    latest_log_offset = self.get_lastest_log_offset()
  File "/home/exbot/code/python/tornado/Tjango/contrib/admin/log.py", line 21, in get_lastest_log_offset
    BaseHandler.prepare(self)
  File "/home/exbot/code/python/tornado/Tjango/contrib/admin/view.py", line 18, in prepare
    database.connect()
  File "/usr/local/lib/python2.7/dist-packages/peewee.py", line 3669, in connect
    raise OperationalError('Connection already open')
OperationalError: Connection already open
2017-05-12 16:54:01,106 - tornado.application - ERROR - Exception in callback <function praseLog at 0x7ff15b1f7578>
Traceback (most recent call last):
  File "/usr/local/lib/python2.7/dist-packages/tornado/ioloop.py", line 1026, in _run
    return self.callback()
  File "/home/exbot/code/python/tornado/Tjango/contrib/admin/log.py", line 94, in praseLog
    a.parase_log()
  File "/home/exbot/code/python/tornado/Tjango/contrib/admin/log.py", line 33, in parase_log
    latest_log_offset = self.get_lastest_log_offset()
  File "/home/exbot/code/python/tornado/Tjango/contrib/admin/log.py", line 21, in get_lastest_log_offset
    BaseHandler.prepare(self)
  File "/home/exbot/code/python/tornado/Tjango/contrib/admin/view.py", line 18, in prepare
    database.connect()
  File "/usr/local/lib/python2.7/dist-packages/peewee.py", line 3669, in connect
    raise OperationalError('Connection already open')
OperationalError: Connection already open
2017-05-12 17:04:01,147 - tornado.application - ERROR - Exception in callback <function praseLog at 0x7ff15b1f7578>
Traceback (most recent call last):
  File "/usr/local/lib/python2.7/dist-packages/tornado/ioloop.py", line 1026, in _run
    return self.callback()
  File "/home/exbot/code/python/tornado/Tjango/contrib/admin/log.py", line 94, in praseLog
    a.parase_log()
  File "/home/exbot/code/python/tornado/Tjango/contrib/admin/log.py", line 33, in parase_log
    latest_log_offset = self.get_lastest_log_offset()
  File "/home/exbot/code/python/tornado/Tjango/contrib/admin/log.py", line 21, in get_lastest_log_offset
    BaseHandler.prepare(self)
  File "/home/exbot/code/python/tornado/Tjango/contrib/admin/view.py", line 18, in prepare
    database.connect()
  File "/usr/local/lib/python2.7/dist-packages/peewee.py", line 3669, in connect
    raise OperationalError('Connection already open')
OperationalError: Connection already open
2017-05-12 17:14:01,109 - tornado.application - ERROR - Exception in callback <function praseLog at 0x7ff15b1f7578>
Traceback (most recent call last):
  File "/usr/local/lib/python2.7/dist-packages/tornado/ioloop.py", line 1026, in _run
    return self.callback()
  File "/home/exbot/code/python/tornado/Tjango/contrib/admin/log.py", line 94, in praseLog
    a.parase_log()
  File "/home/exbot/code/python/tornado/Tjango/contrib/admin/log.py", line 33, in parase_log
    latest_log_offset = self.get_lastest_log_offset()
  File "/home/exbot/code/python/tornado/Tjango/contrib/admin/log.py", line 21, in get_lastest_log_offset
    BaseHandler.prepare(self)
  File "/home/exbot/code/python/tornado/Tjango/contrib/admin/view.py", line 18, in prepare
    database.connect()
  File "/usr/local/lib/python2.7/dist-packages/peewee.py", line 3669, in connect
    raise OperationalError('Connection already open')
OperationalError: Connection already open
2017-05-12 17:24:01,126 - tornado.application - ERROR - Exception in callback <function praseLog at 0x7ff15b1f7578>
Traceback (most recent call last):
  File "/usr/local/lib/python2.7/dist-packages/tornado/ioloop.py", line 1026, in _run
    return self.callback()
  File "/home/exbot/code/python/tornado/Tjango/contrib/admin/log.py", line 94, in praseLog
    a.parase_log()
  File "/home/exbot/code/python/tornado/Tjango/contrib/admin/log.py", line 33, in parase_log
    latest_log_offset = self.get_lastest_log_offset()
  File "/home/exbot/code/python/tornado/Tjango/contrib/admin/log.py", line 21, in get_lastest_log_offset
    BaseHandler.prepare(self)
  File "/home/exbot/code/python/tornado/Tjango/contrib/admin/view.py", line 18, in prepare
    database.connect()
  File "/usr/local/lib/python2.7/dist-packages/peewee.py", line 3669, in connect
    raise OperationalError('Connection already open')
OperationalError: Connection already open
2017-05-12 17:34:01,143 - tornado.application - ERROR - Exception in callback <function praseLog at 0x7ff15b1f7578>
Traceback (most recent call last):
  File "/usr/local/lib/python2.7/dist-packages/tornado/ioloop.py", line 1026, in _run
    return self.callback()
  File "/home/exbot/code/python/tornado/Tjango/contrib/admin/log.py", line 94, in praseLog
    a.parase_log()
  File "/home/exbot/code/python/tornado/Tjango/contrib/admin/log.py", line 33, in parase_log
    latest_log_offset = self.get_lastest_log_offset()
  File "/home/exbot/code/python/tornado/Tjango/contrib/admin/log.py", line 21, in get_lastest_log_offset
    BaseHandler.prepare(self)
  File "/home/exbot/code/python/tornado/Tjango/contrib/admin/view.py", line 18, in prepare
    database.connect()
  File "/usr/local/lib/python2.7/dist-packages/peewee.py", line 3669, in connect
    raise OperationalError('Connection already open')
OperationalError: Connection already open
2017-05-12 17:44:01,131 - tornado.application - ERROR - Exception in callback <function praseLog at 0x7ff15b1f7578>
Traceback (most recent call last):
  File "/usr/local/lib/python2.7/dist-packages/tornado/ioloop.py", line 1026, in _run
    return self.callback()
  File "/home/exbot/code/python/tornado/Tjango/contrib/admin/log.py", line 94, in praseLog
    a.parase_log()
  File "/home/exbot/code/python/tornado/Tjango/contrib/admin/log.py", line 33, in parase_log
    latest_log_offset = self.get_lastest_log_offset()
  File "/home/exbot/code/python/tornado/Tjango/contrib/admin/log.py", line 21, in get_lastest_log_offset
    BaseHandler.prepare(self)
  File "/home/exbot/code/python/tornado/Tjango/contrib/admin/view.py", line 18, in prepare
    database.connect()
  File "/usr/local/lib/python2.7/dist-packages/peewee.py", line 3669, in connect
    raise OperationalError('Connection already open')
OperationalError: Connection already open
2017-05-12 17:54:01,137 - tornado.application - ERROR - Exception in callback <function praseLog at 0x7ff15b1f7578>
Traceback (most recent call last):
  File "/usr/local/lib/python2.7/dist-packages/tornado/ioloop.py", line 1026, in _run
    return self.callback()
  File "/home/exbot/code/python/tornado/Tjango/contrib/admin/log.py", line 94, in praseLog
    a.parase_log()
  File "/home/exbot/code/python/tornado/Tjango/contrib/admin/log.py", line 33, in parase_log
    latest_log_offset = self.get_lastest_log_offset()
  File "/home/exbot/code/python/tornado/Tjango/contrib/admin/log.py", line 21, in get_lastest_log_offset
    BaseHandler.prepare(self)
  File "/home/exbot/code/python/tornado/Tjango/contrib/admin/view.py", line 18, in prepare
    database.connect()
  File "/usr/local/lib/python2.7/dist-packages/peewee.py", line 3669, in connect
    raise OperationalError('Connection already open')
OperationalError: Connection already open
2017-05-12 18:04:01,150 - tornado.application - ERROR - Exception in callback <function praseLog at 0x7ff15b1f7578>
Traceback (most recent call last):
  File "/usr/local/lib/python2.7/dist-packages/tornado/ioloop.py", line 1026, in _run
    return self.callback()
  File "/home/exbot/code/python/tornado/Tjango/contrib/admin/log.py", line 94, in praseLog
    a.parase_log()
  File "/home/exbot/code/python/tornado/Tjango/contrib/admin/log.py", line 33, in parase_log
    latest_log_offset = self.get_lastest_log_offset()
  File "/home/exbot/code/python/tornado/Tjango/contrib/admin/log.py", line 21, in get_lastest_log_offset
    BaseHandler.prepare(self)
  File "/home/exbot/code/python/tornado/Tjango/contrib/admin/view.py", line 18, in prepare
    database.connect()
  File "/usr/local/lib/python2.7/dist-packages/peewee.py", line 3669, in connect
    raise OperationalError('Connection already open')
OperationalError: Connection already open
2017-05-12 18:14:01,143 - tornado.application - ERROR - Exception in callback <function praseLog at 0x7ff15b1f7578>
Traceback (most recent call last):
  File "/usr/local/lib/python2.7/dist-packages/tornado/ioloop.py", line 1026, in _run
    return self.callback()
  File "/home/exbot/code/python/tornado/Tjango/contrib/admin/log.py", line 94, in praseLog
    a.parase_log()
  File "/home/exbot/code/python/tornado/Tjango/contrib/admin/log.py", line 33, in parase_log
    latest_log_offset = self.get_lastest_log_offset()
  File "/home/exbot/code/python/tornado/Tjango/contrib/admin/log.py", line 21, in get_lastest_log_offset
    BaseHandler.prepare(self)
  File "/home/exbot/code/python/tornado/Tjango/contrib/admin/view.py", line 18, in prepare
    database.connect()
  File "/usr/local/lib/python2.7/dist-packages/peewee.py", line 3669, in connect
    raise OperationalError('Connection already open')
OperationalError: Connection already open
2017-05-12 18:24:01,129 - tornado.application - ERROR - Exception in callback <function praseLog at 0x7ff15b1f7578>
Traceback (most recent call last):
  File "/usr/local/lib/python2.7/dist-packages/tornado/ioloop.py", line 1026, in _run
    return self.callback()
  File "/home/exbot/code/python/tornado/Tjango/contrib/admin/log.py", line 94, in praseLog
    a.parase_log()
  File "/home/exbot/code/python/tornado/Tjango/contrib/admin/log.py", line 33, in parase_log
    latest_log_offset = self.get_lastest_log_offset()
  File "/home/exbot/code/python/tornado/Tjango/contrib/admin/log.py", line 21, in get_lastest_log_offset
    BaseHandler.prepare(self)
  File "/home/exbot/code/python/tornado/Tjango/contrib/admin/view.py", line 18, in prepare
    database.connect()
  File "/usr/local/lib/python2.7/dist-packages/peewee.py", line 3669, in connect
    raise OperationalError('Connection already open')
OperationalError: Connection already open
2017-05-12 18:34:01,051 - tornado.application - ERROR - Exception in callback <function praseLog at 0x7ff15b1f7578>
Traceback (most recent call last):
  File "/usr/local/lib/python2.7/dist-packages/tornado/ioloop.py", line 1026, in _run
    return self.callback()
  File "/home/exbot/code/python/tornado/Tjango/contrib/admin/log.py", line 94, in praseLog
    a.parase_log()
  File "/home/exbot/code/python/tornado/Tjango/contrib/admin/log.py", line 33, in parase_log
    latest_log_offset = self.get_lastest_log_offset()
  File "/home/exbot/code/python/tornado/Tjango/contrib/admin/log.py", line 21, in get_lastest_log_offset
    BaseHandler.prepare(self)
  File "/home/exbot/code/python/tornado/Tjango/contrib/admin/view.py", line 18, in prepare
    database.connect()
  File "/usr/local/lib/python2.7/dist-packages/peewee.py", line 3669, in connect
    raise OperationalError('Connection already open')
OperationalError: Connection already open
2017-05-12 18:44:01,099 - tornado.application - ERROR - Exception in callback <function praseLog at 0x7ff15b1f7578>
Traceback (most recent call last):
  File "/usr/local/lib/python2.7/dist-packages/tornado/ioloop.py", line 1026, in _run
    return self.callback()
  File "/home/exbot/code/python/tornado/Tjango/contrib/admin/log.py", line 94, in praseLog
    a.parase_log()
  File "/home/exbot/code/python/tornado/Tjango/contrib/admin/log.py", line 33, in parase_log
    latest_log_offset = self.get_lastest_log_offset()
  File "/home/exbot/code/python/tornado/Tjango/contrib/admin/log.py", line 21, in get_lastest_log_offset
    BaseHandler.prepare(self)
  File "/home/exbot/code/python/tornado/Tjango/contrib/admin/view.py", line 18, in prepare
    database.connect()
  File "/usr/local/lib/python2.7/dist-packages/peewee.py", line 3669, in connect
    raise OperationalError('Connection already open')
OperationalError: Connection already open
2017-05-12 18:54:01,061 - tornado.application - ERROR - Exception in callback <function praseLog at 0x7ff15b1f7578>
Traceback (most recent call last):
  File "/usr/local/lib/python2.7/dist-packages/tornado/ioloop.py", line 1026, in _run
    return self.callback()
  File "/home/exbot/code/python/tornado/Tjango/contrib/admin/log.py", line 94, in praseLog
    a.parase_log()
  File "/home/exbot/code/python/tornado/Tjango/contrib/admin/log.py", line 33, in parase_log
    latest_log_offset = self.get_lastest_log_offset()
  File "/home/exbot/code/python/tornado/Tjango/contrib/admin/log.py", line 21, in get_lastest_log_offset
    BaseHandler.prepare(self)
  File "/home/exbot/code/python/tornado/Tjango/contrib/admin/view.py", line 18, in prepare
    database.connect()
  File "/usr/local/lib/python2.7/dist-packages/peewee.py", line 3669, in connect
    raise OperationalError('Connection already open')
OperationalError: Connection already open
2017-05-12 19:04:01,085 - tornado.application - ERROR - Exception in callback <function praseLog at 0x7ff15b1f7578>
Traceback (most recent call last):
  File "/usr/local/lib/python2.7/dist-packages/tornado/ioloop.py", line 1026, in _run
    return self.callback()
  File "/home/exbot/code/python/tornado/Tjango/contrib/admin/log.py", line 94, in praseLog
    a.parase_log()
  File "/home/exbot/code/python/tornado/Tjango/contrib/admin/log.py", line 33, in parase_log
    latest_log_offset = self.get_lastest_log_offset()
  File "/home/exbot/code/python/tornado/Tjango/contrib/admin/log.py", line 21, in get_lastest_log_offset
    BaseHandler.prepare(self)
  File "/home/exbot/code/python/tornado/Tjango/contrib/admin/view.py", line 18, in prepare
    database.connect()
  File "/usr/local/lib/python2.7/dist-packages/peewee.py", line 3669, in connect
    raise OperationalError('Connection already open')
OperationalError: Connection already open
2017-05-12 19:14:01,057 - tornado.application - ERROR - Exception in callback <function praseLog at 0x7ff15b1f7578>
Traceback (most recent call last):
  File "/usr/local/lib/python2.7/dist-packages/tornado/ioloop.py", line 1026, in _run
    return self.callback()
  File "/home/exbot/code/python/tornado/Tjango/contrib/admin/log.py", line 94, in praseLog
    a.parase_log()
  File "/home/exbot/code/python/tornado/Tjango/contrib/admin/log.py", line 33, in parase_log
    latest_log_offset = self.get_lastest_log_offset()
  File "/home/exbot/code/python/tornado/Tjango/contrib/admin/log.py", line 21, in get_lastest_log_offset
    BaseHandler.prepare(self)
  File "/home/exbot/code/python/tornado/Tjango/contrib/admin/view.py", line 18, in prepare
    database.connect()
  File "/usr/local/lib/python2.7/dist-packages/peewee.py", line 3669, in connect
    raise OperationalError('Connection already open')
OperationalError: Connection already open
2017-05-12 19:24:01,054 - tornado.application - ERROR - Exception in callback <function praseLog at 0x7ff15b1f7578>
Traceback (most recent call last):
  File "/usr/local/lib/python2.7/dist-packages/tornado/ioloop.py", line 1026, in _run
    return self.callback()
  File "/home/exbot/code/python/tornado/Tjango/contrib/admin/log.py", line 94, in praseLog
    a.parase_log()
  File "/home/exbot/code/python/tornado/Tjango/contrib/admin/log.py", line 33, in parase_log
    latest_log_offset = self.get_lastest_log_offset()
  File "/home/exbot/code/python/tornado/Tjango/contrib/admin/log.py", line 21, in get_lastest_log_offset
    BaseHandler.prepare(self)
  File "/home/exbot/code/python/tornado/Tjango/contrib/admin/view.py", line 18, in prepare
    database.connect()
  File "/usr/local/lib/python2.7/dist-packages/peewee.py", line 3669, in connect
    raise OperationalError('Connection already open')
OperationalError: Connection already open
2017-05-12 19:34:01,083 - tornado.application - ERROR - Exception in callback <function praseLog at 0x7ff15b1f7578>
Traceback (most recent call last):
  File "/usr/local/lib/python2.7/dist-packages/tornado/ioloop.py", line 1026, in _run
    return self.callback()
  File "/home/exbot/code/python/tornado/Tjango/contrib/admin/log.py", line 94, in praseLog
    a.parase_log()
  File "/home/exbot/code/python/tornado/Tjango/contrib/admin/log.py", line 33, in parase_log
    latest_log_offset = self.get_lastest_log_offset()
  File "/home/exbot/code/python/tornado/Tjango/contrib/admin/log.py", line 21, in get_lastest_log_offset
    BaseHandler.prepare(self)
  File "/home/exbot/code/python/tornado/Tjango/contrib/admin/view.py", line 18, in prepare
    database.connect()
  File "/usr/local/lib/python2.7/dist-packages/peewee.py", line 3669, in connect
    raise OperationalError('Connection already open')
OperationalError: Connection already open
2017-05-12 19:44:01,059 - tornado.application - ERROR - Exception in callback <function praseLog at 0x7ff15b1f7578>
Traceback (most recent call last):
  File "/usr/local/lib/python2.7/dist-packages/tornado/ioloop.py", line 1026, in _run
    return self.callback()
  File "/home/exbot/code/python/tornado/Tjango/contrib/admin/log.py", line 94, in praseLog
    a.parase_log()
  File "/home/exbot/code/python/tornado/Tjango/contrib/admin/log.py", line 33, in parase_log
    latest_log_offset = self.get_lastest_log_offset()
  File "/home/exbot/code/python/tornado/Tjango/contrib/admin/log.py", line 21, in get_lastest_log_offset
    BaseHandler.prepare(self)
  File "/home/exbot/code/python/tornado/Tjango/contrib/admin/view.py", line 18, in prepare
    database.connect()
  File "/usr/local/lib/python2.7/dist-packages/peewee.py", line 3669, in connect
    raise OperationalError('Connection already open')
OperationalError: Connection already open
2017-05-12 19:54:01,121 - tornado.application - ERROR - Exception in callback <function praseLog at 0x7ff15b1f7578>
Traceback (most recent call last):
  File "/usr/local/lib/python2.7/dist-packages/tornado/ioloop.py", line 1026, in _run
    return self.callback()
  File "/home/exbot/code/python/tornado/Tjango/contrib/admin/log.py", line 94, in praseLog
    a.parase_log()
  File "/home/exbot/code/python/tornado/Tjango/contrib/admin/log.py", line 33, in parase_log
    latest_log_offset = self.get_lastest_log_offset()
  File "/home/exbot/code/python/tornado/Tjango/contrib/admin/log.py", line 21, in get_lastest_log_offset
    BaseHandler.prepare(self)
  File "/home/exbot/code/python/tornado/Tjango/contrib/admin/view.py", line 18, in prepare
    database.connect()
  File "/usr/local/lib/python2.7/dist-packages/peewee.py", line 3669, in connect
    raise OperationalError('Connection already open')
OperationalError: Connection already open
2017-05-12 20:04:01,091 - tornado.application - ERROR - Exception in callback <function praseLog at 0x7ff15b1f7578>
Traceback (most recent call last):
  File "/usr/local/lib/python2.7/dist-packages/tornado/ioloop.py", line 1026, in _run
    return self.callback()
  File "/home/exbot/code/python/tornado/Tjango/contrib/admin/log.py", line 94, in praseLog
    a.parase_log()
  File "/home/exbot/code/python/tornado/Tjango/contrib/admin/log.py", line 33, in parase_log
    latest_log_offset = self.get_lastest_log_offset()
  File "/home/exbot/code/python/tornado/Tjango/contrib/admin/log.py", line 21, in get_lastest_log_offset
    BaseHandler.prepare(self)
  File "/home/exbot/code/python/tornado/Tjango/contrib/admin/view.py", line 18, in prepare
    database.connect()
  File "/usr/local/lib/python2.7/dist-packages/peewee.py", line 3669, in connect
    raise OperationalError('Connection already open')
OperationalError: Connection already open
2017-05-12 20:14:01,145 - tornado.application - ERROR - Exception in callback <function praseLog at 0x7ff15b1f7578>
Traceback (most recent call last):
  File "/usr/local/lib/python2.7/dist-packages/tornado/ioloop.py", line 1026, in _run
    return self.callback()
  File "/home/exbot/code/python/tornado/Tjango/contrib/admin/log.py", line 94, in praseLog
    a.parase_log()
  File "/home/exbot/code/python/tornado/Tjango/contrib/admin/log.py", line 33, in parase_log
    latest_log_offset = self.get_lastest_log_offset()
  File "/home/exbot/code/python/tornado/Tjango/contrib/admin/log.py", line 21, in get_lastest_log_offset
    BaseHandler.prepare(self)
  File "/home/exbot/code/python/tornado/Tjango/contrib/admin/view.py", line 18, in prepare
    database.connect()
  File "/usr/local/lib/python2.7/dist-packages/peewee.py", line 3669, in connect
    raise OperationalError('Connection already open')
OperationalError: Connection already open
2017-05-12 20:24:01,061 - tornado.application - ERROR - Exception in callback <function praseLog at 0x7ff15b1f7578>
Traceback (most recent call last):
  File "/usr/local/lib/python2.7/dist-packages/tornado/ioloop.py", line 1026, in _run
    return self.callback()
  File "/home/exbot/code/python/tornado/Tjango/contrib/admin/log.py", line 94, in praseLog
    a.parase_log()
  File "/home/exbot/code/python/tornado/Tjango/contrib/admin/log.py", line 33, in parase_log
    latest_log_offset = self.get_lastest_log_offset()
  File "/home/exbot/code/python/tornado/Tjango/contrib/admin/log.py", line 21, in get_lastest_log_offset
    BaseHandler.prepare(self)
  File "/home/exbot/code/python/tornado/Tjango/contrib/admin/view.py", line 18, in prepare
    database.connect()
  File "/usr/local/lib/python2.7/dist-packages/peewee.py", line 3669, in connect
    raise OperationalError('Connection already open')
OperationalError: Connection already open
2017-05-12 20:34:01,122 - tornado.application - ERROR - Exception in callback <function praseLog at 0x7ff15b1f7578>
Traceback (most recent call last):
  File "/usr/local/lib/python2.7/dist-packages/tornado/ioloop.py", line 1026, in _run
    return self.callback()
  File "/home/exbot/code/python/tornado/Tjango/contrib/admin/log.py", line 94, in praseLog
    a.parase_log()
  File "/home/exbot/code/python/tornado/Tjango/contrib/admin/log.py", line 33, in parase_log
    latest_log_offset = self.get_lastest_log_offset()
  File "/home/exbot/code/python/tornado/Tjango/contrib/admin/log.py", line 21, in get_lastest_log_offset
    BaseHandler.prepare(self)
  File "/home/exbot/code/python/tornado/Tjango/contrib/admin/view.py", line 18, in prepare
    database.connect()
  File "/usr/local/lib/python2.7/dist-packages/peewee.py", line 3669, in connect
    raise OperationalError('Connection already open')
OperationalError: Connection already open
2017-05-12 20:44:01,151 - tornado.application - ERROR - Exception in callback <function praseLog at 0x7ff15b1f7578>
Traceback (most recent call last):
  File "/usr/local/lib/python2.7/dist-packages/tornado/ioloop.py", line 1026, in _run
    return self.callback()
  File "/home/exbot/code/python/tornado/Tjango/contrib/admin/log.py", line 94, in praseLog
    a.parase_log()
  File "/home/exbot/code/python/tornado/Tjango/contrib/admin/log.py", line 33, in parase_log
    latest_log_offset = self.get_lastest_log_offset()
  File "/home/exbot/code/python/tornado/Tjango/contrib/admin/log.py", line 21, in get_lastest_log_offset
    BaseHandler.prepare(self)
  File "/home/exbot/code/python/tornado/Tjango/contrib/admin/view.py", line 18, in prepare
    database.connect()
  File "/usr/local/lib/python2.7/dist-packages/peewee.py", line 3669, in connect
    raise OperationalError('Connection already open')
OperationalError: Connection already open
2017-05-12 20:54:01,141 - tornado.application - ERROR - Exception in callback <function praseLog at 0x7ff15b1f7578>
Traceback (most recent call last):
  File "/usr/local/lib/python2.7/dist-packages/tornado/ioloop.py", line 1026, in _run
    return self.callback()
  File "/home/exbot/code/python/tornado/Tjango/contrib/admin/log.py", line 94, in praseLog
    a.parase_log()
  File "/home/exbot/code/python/tornado/Tjango/contrib/admin/log.py", line 33, in parase_log
    latest_log_offset = self.get_lastest_log_offset()
  File "/home/exbot/code/python/tornado/Tjango/contrib/admin/log.py", line 21, in get_lastest_log_offset
    BaseHandler.prepare(self)
  File "/home/exbot/code/python/tornado/Tjango/contrib/admin/view.py", line 18, in prepare
    database.connect()
  File "/usr/local/lib/python2.7/dist-packages/peewee.py", line 3669, in connect
    raise OperationalError('Connection already open')
OperationalError: Connection already open
2017-05-12 21:04:01,118 - tornado.application - ERROR - Exception in callback <function praseLog at 0x7ff15b1f7578>
Traceback (most recent call last):
  File "/usr/local/lib/python2.7/dist-packages/tornado/ioloop.py", line 1026, in _run
    return self.callback()
  File "/home/exbot/code/python/tornado/Tjango/contrib/admin/log.py", line 94, in praseLog
    a.parase_log()
  File "/home/exbot/code/python/tornado/Tjango/contrib/admin/log.py", line 33, in parase_log
    latest_log_offset = self.get_lastest_log_offset()
  File "/home/exbot/code/python/tornado/Tjango/contrib/admin/log.py", line 21, in get_lastest_log_offset
    BaseHandler.prepare(self)
  File "/home/exbot/code/python/tornado/Tjango/contrib/admin/view.py", line 18, in prepare
    database.connect()
  File "/usr/local/lib/python2.7/dist-packages/peewee.py", line 3669, in connect
    raise OperationalError('Connection already open')
OperationalError: Connection already open
2017-05-12 21:14:01,134 - tornado.application - ERROR - Exception in callback <function praseLog at 0x7ff15b1f7578>
Traceback (most recent call last):
  File "/usr/local/lib/python2.7/dist-packages/tornado/ioloop.py", line 1026, in _run
    return self.callback()
  File "/home/exbot/code/python/tornado/Tjango/contrib/admin/log.py", line 94, in praseLog
    a.parase_log()
  File "/home/exbot/code/python/tornado/Tjango/contrib/admin/log.py", line 33, in parase_log
    latest_log_offset = self.get_lastest_log_offset()
  File "/home/exbot/code/python/tornado/Tjango/contrib/admin/log.py", line 21, in get_lastest_log_offset
    BaseHandler.prepare(self)
  File "/home/exbot/code/python/tornado/Tjango/contrib/admin/view.py", line 18, in prepare
    database.connect()
  File "/usr/local/lib/python2.7/dist-packages/peewee.py", line 3669, in connect
    raise OperationalError('Connection already open')
OperationalError: Connection already open
2017-05-12 21:24:01,096 - tornado.application - ERROR - Exception in callback <function praseLog at 0x7ff15b1f7578>
Traceback (most recent call last):
  File "/usr/local/lib/python2.7/dist-packages/tornado/ioloop.py", line 1026, in _run
    return self.callback()
  File "/home/exbot/code/python/tornado/Tjango/contrib/admin/log.py", line 94, in praseLog
    a.parase_log()
  File "/home/exbot/code/python/tornado/Tjango/contrib/admin/log.py", line 33, in parase_log
    latest_log_offset = self.get_lastest_log_offset()
  File "/home/exbot/code/python/tornado/Tjango/contrib/admin/log.py", line 21, in get_lastest_log_offset
    BaseHandler.prepare(self)
  File "/home/exbot/code/python/tornado/Tjango/contrib/admin/view.py", line 18, in prepare
    database.connect()
  File "/usr/local/lib/python2.7/dist-packages/peewee.py", line 3669, in connect
    raise OperationalError('Connection already open')
OperationalError: Connection already open
2017-05-12 21:34:01,138 - tornado.application - ERROR - Exception in callback <function praseLog at 0x7ff15b1f7578>
Traceback (most recent call last):
  File "/usr/local/lib/python2.7/dist-packages/tornado/ioloop.py", line 1026, in _run
    return self.callback()
  File "/home/exbot/code/python/tornado/Tjango/contrib/admin/log.py", line 94, in praseLog
    a.parase_log()
  File "/home/exbot/code/python/tornado/Tjango/contrib/admin/log.py", line 33, in parase_log
    latest_log_offset = self.get_lastest_log_offset()
  File "/home/exbot/code/python/tornado/Tjango/contrib/admin/log.py", line 21, in get_lastest_log_offset
    BaseHandler.prepare(self)
  File "/home/exbot/code/python/tornado/Tjango/contrib/admin/view.py", line 18, in prepare
    database.connect()
  File "/usr/local/lib/python2.7/dist-packages/peewee.py", line 3669, in connect
    raise OperationalError('Connection already open')
OperationalError: Connection already open
2017-05-12 21:44:01,150 - tornado.application - ERROR - Exception in callback <function praseLog at 0x7ff15b1f7578>
Traceback (most recent call last):
  File "/usr/local/lib/python2.7/dist-packages/tornado/ioloop.py", line 1026, in _run
    return self.callback()
  File "/home/exbot/code/python/tornado/Tjango/contrib/admin/log.py", line 94, in praseLog
    a.parase_log()
  File "/home/exbot/code/python/tornado/Tjango/contrib/admin/log.py", line 33, in parase_log
    latest_log_offset = self.get_lastest_log_offset()
  File "/home/exbot/code/python/tornado/Tjango/contrib/admin/log.py", line 21, in get_lastest_log_offset
    BaseHandler.prepare(self)
  File "/home/exbot/code/python/tornado/Tjango/contrib/admin/view.py", line 18, in prepare
    database.connect()
  File "/usr/local/lib/python2.7/dist-packages/peewee.py", line 3669, in connect
    raise OperationalError('Connection already open')
OperationalError: Connection already open
2017-05-12 21:54:01,123 - tornado.application - ERROR - Exception in callback <function praseLog at 0x7ff15b1f7578>
Traceback (most recent call last):
  File "/usr/local/lib/python2.7/dist-packages/tornado/ioloop.py", line 1026, in _run
    return self.callback()
  File "/home/exbot/code/python/tornado/Tjango/contrib/admin/log.py", line 94, in praseLog
    a.parase_log()
  File "/home/exbot/code/python/tornado/Tjango/contrib/admin/log.py", line 33, in parase_log
    latest_log_offset = self.get_lastest_log_offset()
  File "/home/exbot/code/python/tornado/Tjango/contrib/admin/log.py", line 21, in get_lastest_log_offset
    BaseHandler.prepare(self)
  File "/home/exbot/code/python/tornado/Tjango/contrib/admin/view.py", line 18, in prepare
    database.connect()
  File "/usr/local/lib/python2.7/dist-packages/peewee.py", line 3669, in connect
    raise OperationalError('Connection already open')
OperationalError: Connection already open
2017-05-12 22:04:01,143 - tornado.application - ERROR - Exception in callback <function praseLog at 0x7ff15b1f7578>
Traceback (most recent call last):
  File "/usr/local/lib/python2.7/dist-packages/tornado/ioloop.py", line 1026, in _run
    return self.callback()
  File "/home/exbot/code/python/tornado/Tjango/contrib/admin/log.py", line 94, in praseLog
    a.parase_log()
  File "/home/exbot/code/python/tornado/Tjango/contrib/admin/log.py", line 33, in parase_log
    latest_log_offset = self.get_lastest_log_offset()
  File "/home/exbot/code/python/tornado/Tjango/contrib/admin/log.py", line 21, in get_lastest_log_offset
    BaseHandler.prepare(self)
  File "/home/exbot/code/python/tornado/Tjango/contrib/admin/view.py", line 18, in prepare
    database.connect()
  File "/usr/local/lib/python2.7/dist-packages/peewee.py", line 3669, in connect
    raise OperationalError('Connection already open')
OperationalError: Connection already open
2017-05-12 22:14:01,100 - tornado.application - ERROR - Exception in callback <function praseLog at 0x7ff15b1f7578>
Traceback (most recent call last):
  File "/usr/local/lib/python2.7/dist-packages/tornado/ioloop.py", line 1026, in _run
    return self.callback()
  File "/home/exbot/code/python/tornado/Tjango/contrib/admin/log.py", line 94, in praseLog
    a.parase_log()
  File "/home/exbot/code/python/tornado/Tjango/contrib/admin/log.py", line 33, in parase_log
    latest_log_offset = self.get_lastest_log_offset()
  File "/home/exbot/code/python/tornado/Tjango/contrib/admin/log.py", line 21, in get_lastest_log_offset
    BaseHandler.prepare(self)
  File "/home/exbot/code/python/tornado/Tjango/contrib/admin/view.py", line 18, in prepare
    database.connect()
  File "/usr/local/lib/python2.7/dist-packages/peewee.py", line 3669, in connect
    raise OperationalError('Connection already open')
OperationalError: Connection already open
2017-05-12 22:24:01,147 - tornado.application - ERROR - Exception in callback <function praseLog at 0x7ff15b1f7578>
Traceback (most recent call last):
  File "/usr/local/lib/python2.7/dist-packages/tornado/ioloop.py", line 1026, in _run
    return self.callback()
  File "/home/exbot/code/python/tornado/Tjango/contrib/admin/log.py", line 94, in praseLog
    a.parase_log()
  File "/home/exbot/code/python/tornado/Tjango/contrib/admin/log.py", line 33, in parase_log
    latest_log_offset = self.get_lastest_log_offset()
  File "/home/exbot/code/python/tornado/Tjango/contrib/admin/log.py", line 21, in get_lastest_log_offset
    BaseHandler.prepare(self)
  File "/home/exbot/code/python/tornado/Tjango/contrib/admin/view.py", line 18, in prepare
    database.connect()
  File "/usr/local/lib/python2.7/dist-packages/peewee.py", line 3669, in connect
    raise OperationalError('Connection already open')
OperationalError: Connection already open
2017-05-12 22:34:01,134 - tornado.application - ERROR - Exception in callback <function praseLog at 0x7ff15b1f7578>
Traceback (most recent call last):
  File "/usr/local/lib/python2.7/dist-packages/tornado/ioloop.py", line 1026, in _run
    return self.callback()
  File "/home/exbot/code/python/tornado/Tjango/contrib/admin/log.py", line 94, in praseLog
    a.parase_log()
  File "/home/exbot/code/python/tornado/Tjango/contrib/admin/log.py", line 33, in parase_log
    latest_log_offset = self.get_lastest_log_offset()
  File "/home/exbot/code/python/tornado/Tjango/contrib/admin/log.py", line 21, in get_lastest_log_offset
    BaseHandler.prepare(self)
  File "/home/exbot/code/python/tornado/Tjango/contrib/admin/view.py", line 18, in prepare
    database.connect()
  File "/usr/local/lib/python2.7/dist-packages/peewee.py", line 3669, in connect
    raise OperationalError('Connection already open')
OperationalError: Connection already open
2017-05-12 22:44:01,134 - tornado.application - ERROR - Exception in callback <function praseLog at 0x7ff15b1f7578>
Traceback (most recent call last):
  File "/usr/local/lib/python2.7/dist-packages/tornado/ioloop.py", line 1026, in _run
    return self.callback()
  File "/home/exbot/code/python/tornado/Tjango/contrib/admin/log.py", line 94, in praseLog
    a.parase_log()
  File "/home/exbot/code/python/tornado/Tjango/contrib/admin/log.py", line 33, in parase_log
    latest_log_offset = self.get_lastest_log_offset()
  File "/home/exbot/code/python/tornado/Tjango/contrib/admin/log.py", line 21, in get_lastest_log_offset
    BaseHandler.prepare(self)
  File "/home/exbot/code/python/tornado/Tjango/contrib/admin/view.py", line 18, in prepare
    database.connect()
  File "/usr/local/lib/python2.7/dist-packages/peewee.py", line 3669, in connect
    raise OperationalError('Connection already open')
OperationalError: Connection already open
2017-05-12 22:54:01,144 - tornado.application - ERROR - Exception in callback <function praseLog at 0x7ff15b1f7578>
Traceback (most recent call last):
  File "/usr/local/lib/python2.7/dist-packages/tornado/ioloop.py", line 1026, in _run
    return self.callback()
  File "/home/exbot/code/python/tornado/Tjango/contrib/admin/log.py", line 94, in praseLog
    a.parase_log()
  File "/home/exbot/code/python/tornado/Tjango/contrib/admin/log.py", line 33, in parase_log
    latest_log_offset = self.get_lastest_log_offset()
  File "/home/exbot/code/python/tornado/Tjango/contrib/admin/log.py", line 21, in get_lastest_log_offset
    BaseHandler.prepare(self)
  File "/home/exbot/code/python/tornado/Tjango/contrib/admin/view.py", line 18, in prepare
    database.connect()
  File "/usr/local/lib/python2.7/dist-packages/peewee.py", line 3669, in connect
    raise OperationalError('Connection already open')
OperationalError: Connection already open
2017-05-12 23:04:01,097 - tornado.application - ERROR - Exception in callback <function praseLog at 0x7ff15b1f7578>
Traceback (most recent call last):
  File "/usr/local/lib/python2.7/dist-packages/tornado/ioloop.py", line 1026, in _run
    return self.callback()
  File "/home/exbot/code/python/tornado/Tjango/contrib/admin/log.py", line 94, in praseLog
    a.parase_log()
  File "/home/exbot/code/python/tornado/Tjango/contrib/admin/log.py", line 33, in parase_log
    latest_log_offset = self.get_lastest_log_offset()
  File "/home/exbot/code/python/tornado/Tjango/contrib/admin/log.py", line 21, in get_lastest_log_offset
    BaseHandler.prepare(self)
  File "/home/exbot/code/python/tornado/Tjango/contrib/admin/view.py", line 18, in prepare
    database.connect()
  File "/usr/local/lib/python2.7/dist-packages/peewee.py", line 3669, in connect
    raise OperationalError('Connection already open')
OperationalError: Connection already open
2017-05-12 23:14:01,051 - tornado.application - ERROR - Exception in callback <function praseLog at 0x7ff15b1f7578>
Traceback (most recent call last):
  File "/usr/local/lib/python2.7/dist-packages/tornado/ioloop.py", line 1026, in _run
    return self.callback()
  File "/home/exbot/code/python/tornado/Tjango/contrib/admin/log.py", line 94, in praseLog
    a.parase_log()
  File "/home/exbot/code/python/tornado/Tjango/contrib/admin/log.py", line 33, in parase_log
    latest_log_offset = self.get_lastest_log_offset()
  File "/home/exbot/code/python/tornado/Tjango/contrib/admin/log.py", line 21, in get_lastest_log_offset
    BaseHandler.prepare(self)
  File "/home/exbot/code/python/tornado/Tjango/contrib/admin/view.py", line 18, in prepare
    database.connect()
  File "/usr/local/lib/python2.7/dist-packages/peewee.py", line 3669, in connect
    raise OperationalError('Connection already open')
OperationalError: Connection already open
2017-05-12 23:24:01,147 - tornado.application - ERROR - Exception in callback <function praseLog at 0x7ff15b1f7578>
Traceback (most recent call last):
  File "/usr/local/lib/python2.7/dist-packages/tornado/ioloop.py", line 1026, in _run
    return self.callback()
  File "/home/exbot/code/python/tornado/Tjango/contrib/admin/log.py", line 94, in praseLog
    a.parase_log()
  File "/home/exbot/code/python/tornado/Tjango/contrib/admin/log.py", line 33, in parase_log
    latest_log_offset = self.get_lastest_log_offset()
  File "/home/exbot/code/python/tornado/Tjango/contrib/admin/log.py", line 21, in get_lastest_log_offset
    BaseHandler.prepare(self)
  File "/home/exbot/code/python/tornado/Tjango/contrib/admin/view.py", line 18, in prepare
    database.connect()
  File "/usr/local/lib/python2.7/dist-packages/peewee.py", line 3669, in connect
    raise OperationalError('Connection already open')
OperationalError: Connection already open
2017-05-12 23:34:01,113 - tornado.application - ERROR - Exception in callback <function praseLog at 0x7ff15b1f7578>
Traceback (most recent call last):
  File "/usr/local/lib/python2.7/dist-packages/tornado/ioloop.py", line 1026, in _run
    return self.callback()
  File "/home/exbot/code/python/tornado/Tjango/contrib/admin/log.py", line 94, in praseLog
    a.parase_log()
  File "/home/exbot/code/python/tornado/Tjango/contrib/admin/log.py", line 33, in parase_log
    latest_log_offset = self.get_lastest_log_offset()
  File "/home/exbot/code/python/tornado/Tjango/contrib/admin/log.py", line 21, in get_lastest_log_offset
    BaseHandler.prepare(self)
  File "/home/exbot/code/python/tornado/Tjango/contrib/admin/view.py", line 18, in prepare
    database.connect()
  File "/usr/local/lib/python2.7/dist-packages/peewee.py", line 3669, in connect
    raise OperationalError('Connection already open')
OperationalError: Connection already open
2017-05-12 23:44:01,146 - tornado.application - ERROR - Exception in callback <function praseLog at 0x7ff15b1f7578>
Traceback (most recent call last):
  File "/usr/local/lib/python2.7/dist-packages/tornado/ioloop.py", line 1026, in _run
    return self.callback()
  File "/home/exbot/code/python/tornado/Tjango/contrib/admin/log.py", line 94, in praseLog
    a.parase_log()
  File "/home/exbot/code/python/tornado/Tjango/contrib/admin/log.py", line 33, in parase_log
    latest_log_offset = self.get_lastest_log_offset()
  File "/home/exbot/code/python/tornado/Tjango/contrib/admin/log.py", line 21, in get_lastest_log_offset
    BaseHandler.prepare(self)
  File "/home/exbot/code/python/tornado/Tjango/contrib/admin/view.py", line 18, in prepare
    database.connect()
  File "/usr/local/lib/python2.7/dist-packages/peewee.py", line 3669, in connect
    raise OperationalError('Connection already open')
OperationalError: Connection already open
2017-05-12 23:54:01,077 - tornado.application - ERROR - Exception in callback <function praseLog at 0x7ff15b1f7578>
Traceback (most recent call last):
  File "/usr/local/lib/python2.7/dist-packages/tornado/ioloop.py", line 1026, in _run
    return self.callback()
  File "/home/exbot/code/python/tornado/Tjango/contrib/admin/log.py", line 94, in praseLog
    a.parase_log()
  File "/home/exbot/code/python/tornado/Tjango/contrib/admin/log.py", line 33, in parase_log
    latest_log_offset = self.get_lastest_log_offset()
  File "/home/exbot/code/python/tornado/Tjango/contrib/admin/log.py", line 21, in get_lastest_log_offset
    BaseHandler.prepare(self)
  File "/home/exbot/code/python/tornado/Tjango/contrib/admin/view.py", line 18, in prepare
    database.connect()
  File "/usr/local/lib/python2.7/dist-packages/peewee.py", line 3669, in connect
    raise OperationalError('Connection already open')
OperationalError: Connection already open
